2018-10-05 04:29:45 [analysis_log] ERROR: into_Sellers_list
Traceback (most recent call last):
  File "/usr/lib/python3/dist-packages/urllib3/connectionpool.py", line 555, in urlopen
    self._prepare_proxy(conn)
  File "/usr/lib/python3/dist-packages/urllib3/connectionpool.py", line 753, in _prepare_proxy
    conn.connect()
  File "/usr/lib/python3/dist-packages/urllib3/connection.py", line 230, in connect
    self._tunnel()
  File "/usr/lib/python3.5/http/client.py", line 827, in _tunnel
    (version, code, message) = response._read_status()
  File "/usr/lib/python3.5/http/client.py", line 258, in _read_status
    line = str(self.fp.readline(_MAXLINE + 1), "iso-8859-1")
  File "/usr/lib/python3.5/socket.py", line 575, in readinto
    return self._sock.recv_into(b)
ConnectionResetError: [Errno 104] Connection reset by peer

During handling of the above exception, another exception occurred:

Traceback (most recent call last):
  File "/usr/lib/python3/dist-packages/requests/adapters.py", line 376, in send
    timeout=timeout
  File "/usr/lib/python3/dist-packages/urllib3/connectionpool.py", line 610, in urlopen
    _stacktrace=sys.exc_info()[2])
  File "/usr/lib/python3/dist-packages/urllib3/util/retry.py", line 273, in increment
    raise MaxRetryError(_pool, url, error or ResponseError(cause))
requests.packages.urllib3.exceptions.MaxRetryError: HTTPSConnectionPool(host='www.amazon.com', port=443): Max retries exceeded with url: /gp/offer-listing/B000A7QJKI/ref=dp_olp_all_mbc?ie=UTF8&condition=all (Caused by ProxyError('Cannot connect to proxy.', ConnectionResetError(104, 'Connection reset by peer')))

During handling of the above exception, another exception occurred:

Traceback (most recent call last):
  File "/root/Xuggest_scrapy/AMA_ANALYSIS/analysis_request_header.py", line 300, in into_Sellers_list
    sellers_list_responses = myrequest_get(url=sellers_list_url,headers=headers)
  File "/root/Xuggest_scrapy/AMA_ANALYSIS/analysis_request_header.py", line 256, in myrequest_get
    timeout=20
  File "/usr/lib/python3/dist-packages/requests/api.py", line 67, in get
    return request('get', url, params=params, **kwargs)
  File "/usr/lib/python3/dist-packages/requests/api.py", line 53, in request
    return session.request(method=method, url=url, **kwargs)
  File "/usr/lib/python3/dist-packages/requests/sessions.py", line 468, in request
    resp = self.send(prep, **send_kwargs)
  File "/usr/lib/python3/dist-packages/requests/sessions.py", line 576, in send
    r = adapter.send(request, **kwargs)
  File "/usr/lib/python3/dist-packages/requests/adapters.py", line 437, in send
    raise ConnectionError(e, request=request)
requests.exceptions.ConnectionError: HTTPSConnectionPool(host='www.amazon.com', port=443): Max retries exceeded with url: /gp/offer-listing/B000A7QJKI/ref=dp_olp_all_mbc?ie=UTF8&condition=all (Caused by ProxyError('Cannot connect to proxy.', ConnectionResetError(104, 'Connection reset by peer')))
2018-10-05 04:29:48 [analysis_log] ERROR: into_Sellers_list
Traceback (most recent call last):
  File "/usr/lib/python3/dist-packages/urllib3/connectionpool.py", line 555, in urlopen
    self._prepare_proxy(conn)
  File "/usr/lib/python3/dist-packages/urllib3/connectionpool.py", line 753, in _prepare_proxy
    conn.connect()
  File "/usr/lib/python3/dist-packages/urllib3/connection.py", line 230, in connect
    self._tunnel()
  File "/usr/lib/python3.5/http/client.py", line 827, in _tunnel
    (version, code, message) = response._read_status()
  File "/usr/lib/python3.5/http/client.py", line 258, in _read_status
    line = str(self.fp.readline(_MAXLINE + 1), "iso-8859-1")
  File "/usr/lib/python3.5/socket.py", line 575, in readinto
    return self._sock.recv_into(b)
ConnectionResetError: [Errno 104] Connection reset by peer

During handling of the above exception, another exception occurred:

Traceback (most recent call last):
  File "/usr/lib/python3/dist-packages/requests/adapters.py", line 376, in send
    timeout=timeout
  File "/usr/lib/python3/dist-packages/urllib3/connectionpool.py", line 610, in urlopen
    _stacktrace=sys.exc_info()[2])
  File "/usr/lib/python3/dist-packages/urllib3/util/retry.py", line 273, in increment
    raise MaxRetryError(_pool, url, error or ResponseError(cause))
requests.packages.urllib3.exceptions.MaxRetryError: HTTPSConnectionPool(host='www.amazon.com', port=443): Max retries exceeded with url: /gp/offer-listing/B000A7QJKI/ref=dp_olp_all_mbc?ie=UTF8&condition=all (Caused by ProxyError('Cannot connect to proxy.', ConnectionResetError(104, 'Connection reset by peer')))

During handling of the above exception, another exception occurred:

Traceback (most recent call last):
  File "/root/Xuggest_scrapy/AMA_ANALYSIS/analysis_request_header.py", line 300, in into_Sellers_list
    sellers_list_responses = myrequest_get(url=sellers_list_url,headers=headers)
  File "/root/Xuggest_scrapy/AMA_ANALYSIS/analysis_request_header.py", line 256, in myrequest_get
    timeout=20
  File "/usr/lib/python3/dist-packages/requests/api.py", line 67, in get
    return request('get', url, params=params, **kwargs)
  File "/usr/lib/python3/dist-packages/requests/api.py", line 53, in request
    return session.request(method=method, url=url, **kwargs)
  File "/usr/lib/python3/dist-packages/requests/sessions.py", line 468, in request
    resp = self.send(prep, **send_kwargs)
  File "/usr/lib/python3/dist-packages/requests/sessions.py", line 576, in send
    r = adapter.send(request, **kwargs)
  File "/usr/lib/python3/dist-packages/requests/adapters.py", line 437, in send
    raise ConnectionError(e, request=request)
requests.exceptions.ConnectionError: HTTPSConnectionPool(host='www.amazon.com', port=443): Max retries exceeded with url: /gp/offer-listing/B000A7QJKI/ref=dp_olp_all_mbc?ie=UTF8&condition=all (Caused by ProxyError('Cannot connect to proxy.', ConnectionResetError(104, 'Connection reset by peer')))
2018-10-05 04:29:48 [analysis_log] ERROR: sellers_list_responses
Traceback (most recent call last):
  File "/root/Xuggest_scrapy/AMA_ANALYSIS/USA_analysis.py", line 1067, in Available
    sellers_list_responses = into_Sellers_list(sellers_list_url)
  File "/root/Xuggest_scrapy/AMA_ANALYSIS/analysis_request_header.py", line 305, in into_Sellers_list
    return sellers_list_responses
UnboundLocalError: local variable 'sellers_list_responses' referenced before assignment
2018-10-05 04:29:48 [analysis_log] ERROR: USA_USA_second_Analysis
Traceback (most recent call last):
  File "/root/Xuggest_scrapy/AMA_ANALYSIS/use_analysis.py", line 79, in USA_analysis
    USA_second_Analysis(ASIN=ASIN,stock=Stock,sellers_list_url=sellers_list_url,product_info=product_info,offerListingID=offerListingID)
  File "/root/Xuggest_scrapy/AMA_ANALYSIS/USA_analysis.py", line 1198, in USA_second_Analysis
    usa_second_product_obj.Available(sellers_list_url=sellers_list_url,ASIN=ASIN)
  File "/root/Xuggest_scrapy/AMA_ANALYSIS/USA_analysis.py", line 1072, in Available
    etree_html = etree.HTML(sellers_list_responses)
UnboundLocalError: local variable 'sellers_list_responses' referenced before assignment
2018-10-05 04:30:36 [analysis_log] ERROR: into_Sellers_list
Traceback (most recent call last):
  File "/usr/lib/python3/dist-packages/urllib3/connectionpool.py", line 555, in urlopen
    self._prepare_proxy(conn)
  File "/usr/lib/python3/dist-packages/urllib3/connectionpool.py", line 753, in _prepare_proxy
    conn.connect()
  File "/usr/lib/python3/dist-packages/urllib3/connection.py", line 230, in connect
    self._tunnel()
  File "/usr/lib/python3.5/http/client.py", line 827, in _tunnel
    (version, code, message) = response._read_status()
  File "/usr/lib/python3.5/http/client.py", line 258, in _read_status
    line = str(self.fp.readline(_MAXLINE + 1), "iso-8859-1")
  File "/usr/lib/python3.5/socket.py", line 575, in readinto
    return self._sock.recv_into(b)
ConnectionResetError: [Errno 104] Connection reset by peer

During handling of the above exception, another exception occurred:

Traceback (most recent call last):
  File "/usr/lib/python3/dist-packages/requests/adapters.py", line 376, in send
    timeout=timeout
  File "/usr/lib/python3/dist-packages/urllib3/connectionpool.py", line 610, in urlopen
    _stacktrace=sys.exc_info()[2])
  File "/usr/lib/python3/dist-packages/urllib3/util/retry.py", line 273, in increment
    raise MaxRetryError(_pool, url, error or ResponseError(cause))
requests.packages.urllib3.exceptions.MaxRetryError: HTTPSConnectionPool(host='www.amazon.com', port=443): Max retries exceeded with url: /gp/offer-listing/B013PYGNLW/ref=dp_olp_new_mbc?ie=UTF8&condition=new (Caused by ProxyError('Cannot connect to proxy.', ConnectionResetError(104, 'Connection reset by peer')))

During handling of the above exception, another exception occurred:

Traceback (most recent call last):
  File "/root/Xuggest_scrapy/AMA_ANALYSIS/analysis_request_header.py", line 300, in into_Sellers_list
    sellers_list_responses = myrequest_get(url=sellers_list_url,headers=headers)
  File "/root/Xuggest_scrapy/AMA_ANALYSIS/analysis_request_header.py", line 256, in myrequest_get
    timeout=20
  File "/usr/lib/python3/dist-packages/requests/api.py", line 67, in get
    return request('get', url, params=params, **kwargs)
  File "/usr/lib/python3/dist-packages/requests/api.py", line 53, in request
    return session.request(method=method, url=url, **kwargs)
  File "/usr/lib/python3/dist-packages/requests/sessions.py", line 468, in request
    resp = self.send(prep, **send_kwargs)
  File "/usr/lib/python3/dist-packages/requests/sessions.py", line 576, in send
    r = adapter.send(request, **kwargs)
  File "/usr/lib/python3/dist-packages/requests/adapters.py", line 437, in send
    raise ConnectionError(e, request=request)
requests.exceptions.ConnectionError: HTTPSConnectionPool(host='www.amazon.com', port=443): Max retries exceeded with url: /gp/offer-listing/B013PYGNLW/ref=dp_olp_new_mbc?ie=UTF8&condition=new (Caused by ProxyError('Cannot connect to proxy.', ConnectionResetError(104, 'Connection reset by peer')))
2018-10-05 04:30:37 [analysis_log] ERROR: into_Sellers_list
Traceback (most recent call last):
  File "/usr/lib/python3/dist-packages/urllib3/connectionpool.py", line 555, in urlopen
    self._prepare_proxy(conn)
  File "/usr/lib/python3/dist-packages/urllib3/connectionpool.py", line 753, in _prepare_proxy
    conn.connect()
  File "/usr/lib/python3/dist-packages/urllib3/connection.py", line 230, in connect
    self._tunnel()
  File "/usr/lib/python3.5/http/client.py", line 827, in _tunnel
    (version, code, message) = response._read_status()
  File "/usr/lib/python3.5/http/client.py", line 258, in _read_status
    line = str(self.fp.readline(_MAXLINE + 1), "iso-8859-1")
  File "/usr/lib/python3.5/socket.py", line 575, in readinto
    return self._sock.recv_into(b)
ConnectionResetError: [Errno 104] Connection reset by peer

During handling of the above exception, another exception occurred:

Traceback (most recent call last):
  File "/usr/lib/python3/dist-packages/requests/adapters.py", line 376, in send
    timeout=timeout
  File "/usr/lib/python3/dist-packages/urllib3/connectionpool.py", line 610, in urlopen
    _stacktrace=sys.exc_info()[2])
  File "/usr/lib/python3/dist-packages/urllib3/util/retry.py", line 273, in increment
    raise MaxRetryError(_pool, url, error or ResponseError(cause))
requests.packages.urllib3.exceptions.MaxRetryError: HTTPSConnectionPool(host='www.amazon.com', port=443): Max retries exceeded with url: /gp/offer-listing/B013PYGNLW/ref=dp_olp_new_mbc?ie=UTF8&condition=new (Caused by ProxyError('Cannot connect to proxy.', ConnectionResetError(104, 'Connection reset by peer')))

During handling of the above exception, another exception occurred:

Traceback (most recent call last):
  File "/root/Xuggest_scrapy/AMA_ANALYSIS/analysis_request_header.py", line 300, in into_Sellers_list
    sellers_list_responses = myrequest_get(url=sellers_list_url,headers=headers)
  File "/root/Xuggest_scrapy/AMA_ANALYSIS/analysis_request_header.py", line 256, in myrequest_get
    timeout=20
  File "/usr/lib/python3/dist-packages/requests/api.py", line 67, in get
    return request('get', url, params=params, **kwargs)
  File "/usr/lib/python3/dist-packages/requests/api.py", line 53, in request
    return session.request(method=method, url=url, **kwargs)
  File "/usr/lib/python3/dist-packages/requests/sessions.py", line 468, in request
    resp = self.send(prep, **send_kwargs)
  File "/usr/lib/python3/dist-packages/requests/sessions.py", line 576, in send
    r = adapter.send(request, **kwargs)
  File "/usr/lib/python3/dist-packages/requests/adapters.py", line 437, in send
    raise ConnectionError(e, request=request)
requests.exceptions.ConnectionError: HTTPSConnectionPool(host='www.amazon.com', port=443): Max retries exceeded with url: /gp/offer-listing/B013PYGNLW/ref=dp_olp_new_mbc?ie=UTF8&condition=new (Caused by ProxyError('Cannot connect to proxy.', ConnectionResetError(104, 'Connection reset by peer')))
2018-10-05 04:30:37 [analysis_log] ERROR: sellers_list_responses
Traceback (most recent call last):
  File "/root/Xuggest_scrapy/AMA_ANALYSIS/USA_analysis.py", line 1067, in Available
    sellers_list_responses = into_Sellers_list(sellers_list_url)
  File "/root/Xuggest_scrapy/AMA_ANALYSIS/analysis_request_header.py", line 305, in into_Sellers_list
    return sellers_list_responses
UnboundLocalError: local variable 'sellers_list_responses' referenced before assignment
2018-10-05 04:30:37 [analysis_log] ERROR: USA_USA_second_Analysis
Traceback (most recent call last):
  File "/root/Xuggest_scrapy/AMA_ANALYSIS/use_analysis.py", line 79, in USA_analysis
    USA_second_Analysis(ASIN=ASIN,stock=Stock,sellers_list_url=sellers_list_url,product_info=product_info,offerListingID=offerListingID)
  File "/root/Xuggest_scrapy/AMA_ANALYSIS/USA_analysis.py", line 1198, in USA_second_Analysis
    usa_second_product_obj.Available(sellers_list_url=sellers_list_url,ASIN=ASIN)
  File "/root/Xuggest_scrapy/AMA_ANALYSIS/USA_analysis.py", line 1072, in Available
    etree_html = etree.HTML(sellers_list_responses)
UnboundLocalError: local variable 'sellers_list_responses' referenced before assignment
2018-10-05 04:30:50 [analysis_log] ERROR: into_Sellers_list
Traceback (most recent call last):
  File "/usr/lib/python3/dist-packages/urllib3/connectionpool.py", line 555, in urlopen
    self._prepare_proxy(conn)
  File "/usr/lib/python3/dist-packages/urllib3/connectionpool.py", line 753, in _prepare_proxy
    conn.connect()
  File "/usr/lib/python3/dist-packages/urllib3/connection.py", line 230, in connect
    self._tunnel()
  File "/usr/lib/python3.5/http/client.py", line 827, in _tunnel
    (version, code, message) = response._read_status()
  File "/usr/lib/python3.5/http/client.py", line 258, in _read_status
    line = str(self.fp.readline(_MAXLINE + 1), "iso-8859-1")
  File "/usr/lib/python3.5/socket.py", line 575, in readinto
    return self._sock.recv_into(b)
ConnectionResetError: [Errno 104] Connection reset by peer

During handling of the above exception, another exception occurred:

Traceback (most recent call last):
  File "/usr/lib/python3/dist-packages/requests/adapters.py", line 376, in send
    timeout=timeout
  File "/usr/lib/python3/dist-packages/urllib3/connectionpool.py", line 610, in urlopen
    _stacktrace=sys.exc_info()[2])
  File "/usr/lib/python3/dist-packages/urllib3/util/retry.py", line 273, in increment
    raise MaxRetryError(_pool, url, error or ResponseError(cause))
requests.packages.urllib3.exceptions.MaxRetryError: HTTPSConnectionPool(host='www.amazon.com', port=443): Max retries exceeded with url: /gp/offer-listing/B01MT42GZR/ref=dp_olp_new_mbc?ie=UTF8&condition=new (Caused by ProxyError('Cannot connect to proxy.', ConnectionResetError(104, 'Connection reset by peer')))

During handling of the above exception, another exception occurred:

Traceback (most recent call last):
  File "/root/Xuggest_scrapy/AMA_ANALYSIS/analysis_request_header.py", line 300, in into_Sellers_list
    sellers_list_responses = myrequest_get(url=sellers_list_url,headers=headers)
  File "/root/Xuggest_scrapy/AMA_ANALYSIS/analysis_request_header.py", line 256, in myrequest_get
    timeout=20
  File "/usr/lib/python3/dist-packages/requests/api.py", line 67, in get
    return request('get', url, params=params, **kwargs)
  File "/usr/lib/python3/dist-packages/requests/api.py", line 53, in request
    return session.request(method=method, url=url, **kwargs)
  File "/usr/lib/python3/dist-packages/requests/sessions.py", line 468, in request
    resp = self.send(prep, **send_kwargs)
  File "/usr/lib/python3/dist-packages/requests/sessions.py", line 576, in send
    r = adapter.send(request, **kwargs)
  File "/usr/lib/python3/dist-packages/requests/adapters.py", line 437, in send
    raise ConnectionError(e, request=request)
requests.exceptions.ConnectionError: HTTPSConnectionPool(host='www.amazon.com', port=443): Max retries exceeded with url: /gp/offer-listing/B01MT42GZR/ref=dp_olp_new_mbc?ie=UTF8&condition=new (Caused by ProxyError('Cannot connect to proxy.', ConnectionResetError(104, 'Connection reset by peer')))
2018-10-05 04:30:50 [analysis_log] ERROR: into_Sellers_list
Traceback (most recent call last):
  File "/usr/lib/python3/dist-packages/urllib3/connectionpool.py", line 555, in urlopen
    self._prepare_proxy(conn)
  File "/usr/lib/python3/dist-packages/urllib3/connectionpool.py", line 753, in _prepare_proxy
    conn.connect()
  File "/usr/lib/python3/dist-packages/urllib3/connection.py", line 230, in connect
    self._tunnel()
  File "/usr/lib/python3.5/http/client.py", line 827, in _tunnel
    (version, code, message) = response._read_status()
  File "/usr/lib/python3.5/http/client.py", line 258, in _read_status
    line = str(self.fp.readline(_MAXLINE + 1), "iso-8859-1")
  File "/usr/lib/python3.5/socket.py", line 575, in readinto
    return self._sock.recv_into(b)
ConnectionResetError: [Errno 104] Connection reset by peer

During handling of the above exception, another exception occurred:

Traceback (most recent call last):
  File "/usr/lib/python3/dist-packages/requests/adapters.py", line 376, in send
    timeout=timeout
  File "/usr/lib/python3/dist-packages/urllib3/connectionpool.py", line 610, in urlopen
    _stacktrace=sys.exc_info()[2])
  File "/usr/lib/python3/dist-packages/urllib3/util/retry.py", line 273, in increment
    raise MaxRetryError(_pool, url, error or ResponseError(cause))
requests.packages.urllib3.exceptions.MaxRetryError: HTTPSConnectionPool(host='www.amazon.com', port=443): Max retries exceeded with url: /gp/offer-listing/B01MT42GZR/ref=dp_olp_new_mbc?ie=UTF8&condition=new (Caused by ProxyError('Cannot connect to proxy.', ConnectionResetError(104, 'Connection reset by peer')))

During handling of the above exception, another exception occurred:

Traceback (most recent call last):
  File "/root/Xuggest_scrapy/AMA_ANALYSIS/analysis_request_header.py", line 300, in into_Sellers_list
    sellers_list_responses = myrequest_get(url=sellers_list_url,headers=headers)
  File "/root/Xuggest_scrapy/AMA_ANALYSIS/analysis_request_header.py", line 256, in myrequest_get
    timeout=20
  File "/usr/lib/python3/dist-packages/requests/api.py", line 67, in get
    return request('get', url, params=params, **kwargs)
  File "/usr/lib/python3/dist-packages/requests/api.py", line 53, in request
    return session.request(method=method, url=url, **kwargs)
  File "/usr/lib/python3/dist-packages/requests/sessions.py", line 468, in request
    resp = self.send(prep, **send_kwargs)
  File "/usr/lib/python3/dist-packages/requests/sessions.py", line 576, in send
    r = adapter.send(request, **kwargs)
  File "/usr/lib/python3/dist-packages/requests/adapters.py", line 437, in send
    raise ConnectionError(e, request=request)
requests.exceptions.ConnectionError: HTTPSConnectionPool(host='www.amazon.com', port=443): Max retries exceeded with url: /gp/offer-listing/B01MT42GZR/ref=dp_olp_new_mbc?ie=UTF8&condition=new (Caused by ProxyError('Cannot connect to proxy.', ConnectionResetError(104, 'Connection reset by peer')))
2018-10-05 04:30:50 [analysis_log] ERROR: sellers_list_responses
Traceback (most recent call last):
  File "/root/Xuggest_scrapy/AMA_ANALYSIS/USA_analysis.py", line 1067, in Available
    sellers_list_responses = into_Sellers_list(sellers_list_url)
  File "/root/Xuggest_scrapy/AMA_ANALYSIS/analysis_request_header.py", line 305, in into_Sellers_list
    return sellers_list_responses
UnboundLocalError: local variable 'sellers_list_responses' referenced before assignment
2018-10-05 04:30:50 [analysis_log] ERROR: USA_USA_second_Analysis
Traceback (most recent call last):
  File "/root/Xuggest_scrapy/AMA_ANALYSIS/use_analysis.py", line 79, in USA_analysis
    USA_second_Analysis(ASIN=ASIN,stock=Stock,sellers_list_url=sellers_list_url,product_info=product_info,offerListingID=offerListingID)
  File "/root/Xuggest_scrapy/AMA_ANALYSIS/USA_analysis.py", line 1198, in USA_second_Analysis
    usa_second_product_obj.Available(sellers_list_url=sellers_list_url,ASIN=ASIN)
  File "/root/Xuggest_scrapy/AMA_ANALYSIS/USA_analysis.py", line 1072, in Available
    etree_html = etree.HTML(sellers_list_responses)
UnboundLocalError: local variable 'sellers_list_responses' referenced before assignment
2018-10-05 04:31:41 [analysis_log] ERROR: into_Sellers_list
Traceback (most recent call last):
  File "/usr/lib/python3/dist-packages/urllib3/connectionpool.py", line 555, in urlopen
    self._prepare_proxy(conn)
  File "/usr/lib/python3/dist-packages/urllib3/connectionpool.py", line 753, in _prepare_proxy
    conn.connect()
  File "/usr/lib/python3/dist-packages/urllib3/connection.py", line 230, in connect
    self._tunnel()
  File "/usr/lib/python3.5/http/client.py", line 827, in _tunnel
    (version, code, message) = response._read_status()
  File "/usr/lib/python3.5/http/client.py", line 258, in _read_status
    line = str(self.fp.readline(_MAXLINE + 1), "iso-8859-1")
  File "/usr/lib/python3.5/socket.py", line 575, in readinto
    return self._sock.recv_into(b)
ConnectionResetError: [Errno 104] Connection reset by peer

During handling of the above exception, another exception occurred:

Traceback (most recent call last):
  File "/usr/lib/python3/dist-packages/requests/adapters.py", line 376, in send
    timeout=timeout
  File "/usr/lib/python3/dist-packages/urllib3/connectionpool.py", line 610, in urlopen
    _stacktrace=sys.exc_info()[2])
  File "/usr/lib/python3/dist-packages/urllib3/util/retry.py", line 273, in increment
    raise MaxRetryError(_pool, url, error or ResponseError(cause))
requests.packages.urllib3.exceptions.MaxRetryError: HTTPSConnectionPool(host='www.amazon.com', port=443): Max retries exceeded with url: /gp/offer-listing/B00TO7Q70M/ref=dp_olp_new_mbc?ie=UTF8&condition=new (Caused by ProxyError('Cannot connect to proxy.', ConnectionResetError(104, 'Connection reset by peer')))

During handling of the above exception, another exception occurred:

Traceback (most recent call last):
  File "/root/Xuggest_scrapy/AMA_ANALYSIS/analysis_request_header.py", line 300, in into_Sellers_list
    sellers_list_responses = myrequest_get(url=sellers_list_url,headers=headers)
  File "/root/Xuggest_scrapy/AMA_ANALYSIS/analysis_request_header.py", line 256, in myrequest_get
    timeout=20
  File "/usr/lib/python3/dist-packages/requests/api.py", line 67, in get
    return request('get', url, params=params, **kwargs)
  File "/usr/lib/python3/dist-packages/requests/api.py", line 53, in request
    return session.request(method=method, url=url, **kwargs)
  File "/usr/lib/python3/dist-packages/requests/sessions.py", line 468, in request
    resp = self.send(prep, **send_kwargs)
  File "/usr/lib/python3/dist-packages/requests/sessions.py", line 576, in send
    r = adapter.send(request, **kwargs)
  File "/usr/lib/python3/dist-packages/requests/adapters.py", line 437, in send
    raise ConnectionError(e, request=request)
requests.exceptions.ConnectionError: HTTPSConnectionPool(host='www.amazon.com', port=443): Max retries exceeded with url: /gp/offer-listing/B00TO7Q70M/ref=dp_olp_new_mbc?ie=UTF8&condition=new (Caused by ProxyError('Cannot connect to proxy.', ConnectionResetError(104, 'Connection reset by peer')))
2018-10-05 04:31:42 [analysis_log] ERROR: into_Sellers_list
Traceback (most recent call last):
  File "/usr/lib/python3/dist-packages/urllib3/connectionpool.py", line 555, in urlopen
    self._prepare_proxy(conn)
  File "/usr/lib/python3/dist-packages/urllib3/connectionpool.py", line 753, in _prepare_proxy
    conn.connect()
  File "/usr/lib/python3/dist-packages/urllib3/connection.py", line 230, in connect
    self._tunnel()
  File "/usr/lib/python3.5/http/client.py", line 827, in _tunnel
    (version, code, message) = response._read_status()
  File "/usr/lib/python3.5/http/client.py", line 258, in _read_status
    line = str(self.fp.readline(_MAXLINE + 1), "iso-8859-1")
  File "/usr/lib/python3.5/socket.py", line 575, in readinto
    return self._sock.recv_into(b)
ConnectionResetError: [Errno 104] Connection reset by peer

During handling of the above exception, another exception occurred:

Traceback (most recent call last):
  File "/usr/lib/python3/dist-packages/requests/adapters.py", line 376, in send
    timeout=timeout
  File "/usr/lib/python3/dist-packages/urllib3/connectionpool.py", line 610, in urlopen
    _stacktrace=sys.exc_info()[2])
  File "/usr/lib/python3/dist-packages/urllib3/util/retry.py", line 273, in increment
    raise MaxRetryError(_pool, url, error or ResponseError(cause))
requests.packages.urllib3.exceptions.MaxRetryError: HTTPSConnectionPool(host='www.amazon.com', port=443): Max retries exceeded with url: /gp/offer-listing/B00TO7Q70M/ref=dp_olp_new_mbc?ie=UTF8&condition=new (Caused by ProxyError('Cannot connect to proxy.', ConnectionResetError(104, 'Connection reset by peer')))

During handling of the above exception, another exception occurred:

Traceback (most recent call last):
  File "/root/Xuggest_scrapy/AMA_ANALYSIS/analysis_request_header.py", line 300, in into_Sellers_list
    sellers_list_responses = myrequest_get(url=sellers_list_url,headers=headers)
  File "/root/Xuggest_scrapy/AMA_ANALYSIS/analysis_request_header.py", line 256, in myrequest_get
    timeout=20
  File "/usr/lib/python3/dist-packages/requests/api.py", line 67, in get
    return request('get', url, params=params, **kwargs)
  File "/usr/lib/python3/dist-packages/requests/api.py", line 53, in request
    return session.request(method=method, url=url, **kwargs)
  File "/usr/lib/python3/dist-packages/requests/sessions.py", line 468, in request
    resp = self.send(prep, **send_kwargs)
  File "/usr/lib/python3/dist-packages/requests/sessions.py", line 576, in send
    r = adapter.send(request, **kwargs)
  File "/usr/lib/python3/dist-packages/requests/adapters.py", line 437, in send
    raise ConnectionError(e, request=request)
requests.exceptions.ConnectionError: HTTPSConnectionPool(host='www.amazon.com', port=443): Max retries exceeded with url: /gp/offer-listing/B00TO7Q70M/ref=dp_olp_new_mbc?ie=UTF8&condition=new (Caused by ProxyError('Cannot connect to proxy.', ConnectionResetError(104, 'Connection reset by peer')))
2018-10-05 04:31:42 [analysis_log] ERROR: sellers_list_responses
Traceback (most recent call last):
  File "/root/Xuggest_scrapy/AMA_ANALYSIS/USA_analysis.py", line 1067, in Available
    sellers_list_responses = into_Sellers_list(sellers_list_url)
  File "/root/Xuggest_scrapy/AMA_ANALYSIS/analysis_request_header.py", line 305, in into_Sellers_list
    return sellers_list_responses
UnboundLocalError: local variable 'sellers_list_responses' referenced before assignment
2018-10-05 04:31:42 [analysis_log] ERROR: USA_USA_second_Analysis
Traceback (most recent call last):
  File "/root/Xuggest_scrapy/AMA_ANALYSIS/use_analysis.py", line 79, in USA_analysis
    USA_second_Analysis(ASIN=ASIN,stock=Stock,sellers_list_url=sellers_list_url,product_info=product_info,offerListingID=offerListingID)
  File "/root/Xuggest_scrapy/AMA_ANALYSIS/USA_analysis.py", line 1198, in USA_second_Analysis
    usa_second_product_obj.Available(sellers_list_url=sellers_list_url,ASIN=ASIN)
  File "/root/Xuggest_scrapy/AMA_ANALYSIS/USA_analysis.py", line 1072, in Available
    etree_html = etree.HTML(sellers_list_responses)
UnboundLocalError: local variable 'sellers_list_responses' referenced before assignment
2018-10-05 04:32:10 [root] WARNING: 重复处理：https://www.amazon.com/IEason-Women-Pullover-Sleeveless-Waistcoat/dp/B07HJ4D2JQ/ref=zg_bs_8090900011_44?_encoding=UTF8&refRID=6GH6YSJ91GCR8ZYS4EDS
2018-10-05 04:32:14 [root] WARNING: 重复处理：https://www.amazon.com/Clearance-Toimoth-T-Shirt-Blouses-Tops/dp/B07H8YSCQL/ref=zg_bs_8090900011_34?_encoding=UTF8&refRID=6GH6YSJ91GCR8ZYS4EDS
2018-10-05 04:32:33 [root] WARNING: 重复处理：https://www.amazon.com/220-Aran-Stitches-Patterns-Harmony/dp/1855856336/ref=zg_bs_8090900011_52?_encoding=UTF8&psc=1&refRID=N2QVR6NGQYRCM65M08VV
2018-10-05 04:33:04 [root] WARNING: 重复处理：https://www.amazon.com/OCASHI-Womens-Vintage-Sleeve-Outwear/dp/B07GTY8JB8/ref=zg_bs_12899571_66?_encoding=UTF8&refRID=B1TFY70G9V8X6RNRKFTN
2018-10-05 04:33:10 [root] WARNING: 重复处理：https://www.amazon.com/Mnyycxen-Clearance-Lingerie-Bralette-Triangle/dp/B07F73ZVWS/ref=zg_bs_12899571_54?_encoding=UTF8&refRID=B1TFY70G9V8X6RNRKFTN
2018-10-05 04:33:36 [root] WARNING: 重复处理：https://www.amazon.com/Stardust-Micas-Cosmetic-Colorant-Consistency/dp/B078GTYHP6/ref=zg_bs_262710011_85?_encoding=UTF8&psc=1&refRID=YZSCE00W94M0AMFDWQWR
2018-10-05 04:33:40 [root] WARNING: 重复处理：https://www.amazon.com/Clover-Circular-16-Inch-Knitting-Needles/dp/B000WZ2W4A/ref=zg_bs_262624011_93?_encoding=UTF8&psc=1&refRID=EMFTXZDE3BRBVTF52QHF
2018-10-05 04:33:45 [root] WARNING: 重复处理：https://www.amazon.com/Bamboo-Circular-Knitting-Needles-Set/dp/B075ZRX8RQ/ref=zg_bs_262624011_57?_encoding=UTF8&psc=1&refRID=EMFTXZDE3BRBVTF52QHF
2018-10-05 04:34:09 [analysis_log] ERROR: into_Sellers_list
Traceback (most recent call last):
  File "/usr/lib/python3/dist-packages/urllib3/connectionpool.py", line 555, in urlopen
    self._prepare_proxy(conn)
  File "/usr/lib/python3/dist-packages/urllib3/connectionpool.py", line 753, in _prepare_proxy
    conn.connect()
  File "/usr/lib/python3/dist-packages/urllib3/connection.py", line 230, in connect
    self._tunnel()
  File "/usr/lib/python3.5/http/client.py", line 827, in _tunnel
    (version, code, message) = response._read_status()
  File "/usr/lib/python3.5/http/client.py", line 258, in _read_status
    line = str(self.fp.readline(_MAXLINE + 1), "iso-8859-1")
  File "/usr/lib/python3.5/socket.py", line 575, in readinto
    return self._sock.recv_into(b)
ConnectionResetError: [Errno 104] Connection reset by peer

During handling of the above exception, another exception occurred:

Traceback (most recent call last):
  File "/usr/lib/python3/dist-packages/requests/adapters.py", line 376, in send
    timeout=timeout
  File "/usr/lib/python3/dist-packages/urllib3/connectionpool.py", line 610, in urlopen
    _stacktrace=sys.exc_info()[2])
  File "/usr/lib/python3/dist-packages/urllib3/util/retry.py", line 273, in increment
    raise MaxRetryError(_pool, url, error or ResponseError(cause))
requests.packages.urllib3.exceptions.MaxRetryError: HTTPSConnectionPool(host='www.amazon.com', port=443): Max retries exceeded with url: /gp/offer-listing/B0027YYAQC/ref=dp_olp_new_mbc?ie=UTF8&condition=new (Caused by ProxyError('Cannot connect to proxy.', ConnectionResetError(104, 'Connection reset by peer')))

During handling of the above exception, another exception occurred:

Traceback (most recent call last):
  File "/root/Xuggest_scrapy/AMA_ANALYSIS/analysis_request_header.py", line 300, in into_Sellers_list
    sellers_list_responses = myrequest_get(url=sellers_list_url,headers=headers)
  File "/root/Xuggest_scrapy/AMA_ANALYSIS/analysis_request_header.py", line 256, in myrequest_get
    timeout=20
  File "/usr/lib/python3/dist-packages/requests/api.py", line 67, in get
    return request('get', url, params=params, **kwargs)
  File "/usr/lib/python3/dist-packages/requests/api.py", line 53, in request
    return session.request(method=method, url=url, **kwargs)
  File "/usr/lib/python3/dist-packages/requests/sessions.py", line 468, in request
    resp = self.send(prep, **send_kwargs)
  File "/usr/lib/python3/dist-packages/requests/sessions.py", line 576, in send
    r = adapter.send(request, **kwargs)
  File "/usr/lib/python3/dist-packages/requests/adapters.py", line 437, in send
    raise ConnectionError(e, request=request)
requests.exceptions.ConnectionError: HTTPSConnectionPool(host='www.amazon.com', port=443): Max retries exceeded with url: /gp/offer-listing/B0027YYAQC/ref=dp_olp_new_mbc?ie=UTF8&condition=new (Caused by ProxyError('Cannot connect to proxy.', ConnectionResetError(104, 'Connection reset by peer')))
2018-10-05 04:34:09 [analysis_log] ERROR: into_Sellers_list
Traceback (most recent call last):
  File "/usr/lib/python3/dist-packages/urllib3/connectionpool.py", line 555, in urlopen
    self._prepare_proxy(conn)
  File "/usr/lib/python3/dist-packages/urllib3/connectionpool.py", line 753, in _prepare_proxy
    conn.connect()
  File "/usr/lib/python3/dist-packages/urllib3/connection.py", line 230, in connect
    self._tunnel()
  File "/usr/lib/python3.5/http/client.py", line 827, in _tunnel
    (version, code, message) = response._read_status()
  File "/usr/lib/python3.5/http/client.py", line 258, in _read_status
    line = str(self.fp.readline(_MAXLINE + 1), "iso-8859-1")
  File "/usr/lib/python3.5/socket.py", line 575, in readinto
    return self._sock.recv_into(b)
ConnectionResetError: [Errno 104] Connection reset by peer

During handling of the above exception, another exception occurred:

Traceback (most recent call last):
  File "/usr/lib/python3/dist-packages/requests/adapters.py", line 376, in send
    timeout=timeout
  File "/usr/lib/python3/dist-packages/urllib3/connectionpool.py", line 610, in urlopen
    _stacktrace=sys.exc_info()[2])
  File "/usr/lib/python3/dist-packages/urllib3/util/retry.py", line 273, in increment
    raise MaxRetryError(_pool, url, error or ResponseError(cause))
requests.packages.urllib3.exceptions.MaxRetryError: HTTPSConnectionPool(host='www.amazon.com', port=443): Max retries exceeded with url: /gp/offer-listing/B0027YYAQC/ref=dp_olp_new_mbc?ie=UTF8&condition=new (Caused by ProxyError('Cannot connect to proxy.', ConnectionResetError(104, 'Connection reset by peer')))

During handling of the above exception, another exception occurred:

Traceback (most recent call last):
  File "/root/Xuggest_scrapy/AMA_ANALYSIS/analysis_request_header.py", line 300, in into_Sellers_list
    sellers_list_responses = myrequest_get(url=sellers_list_url,headers=headers)
  File "/root/Xuggest_scrapy/AMA_ANALYSIS/analysis_request_header.py", line 256, in myrequest_get
    timeout=20
  File "/usr/lib/python3/dist-packages/requests/api.py", line 67, in get
    return request('get', url, params=params, **kwargs)
  File "/usr/lib/python3/dist-packages/requests/api.py", line 53, in request
    return session.request(method=method, url=url, **kwargs)
  File "/usr/lib/python3/dist-packages/requests/sessions.py", line 468, in request
    resp = self.send(prep, **send_kwargs)
  File "/usr/lib/python3/dist-packages/requests/sessions.py", line 576, in send
    r = adapter.send(request, **kwargs)
  File "/usr/lib/python3/dist-packages/requests/adapters.py", line 437, in send
    raise ConnectionError(e, request=request)
requests.exceptions.ConnectionError: HTTPSConnectionPool(host='www.amazon.com', port=443): Max retries exceeded with url: /gp/offer-listing/B0027YYAQC/ref=dp_olp_new_mbc?ie=UTF8&condition=new (Caused by ProxyError('Cannot connect to proxy.', ConnectionResetError(104, 'Connection reset by peer')))
2018-10-05 04:34:09 [analysis_log] ERROR: sellers_list_responses
Traceback (most recent call last):
  File "/root/Xuggest_scrapy/AMA_ANALYSIS/USA_analysis.py", line 1067, in Available
    sellers_list_responses = into_Sellers_list(sellers_list_url)
  File "/root/Xuggest_scrapy/AMA_ANALYSIS/analysis_request_header.py", line 305, in into_Sellers_list
    return sellers_list_responses
UnboundLocalError: local variable 'sellers_list_responses' referenced before assignment
2018-10-05 04:34:09 [analysis_log] ERROR: USA_USA_second_Analysis
Traceback (most recent call last):
  File "/root/Xuggest_scrapy/AMA_ANALYSIS/use_analysis.py", line 79, in USA_analysis
    USA_second_Analysis(ASIN=ASIN,stock=Stock,sellers_list_url=sellers_list_url,product_info=product_info,offerListingID=offerListingID)
  File "/root/Xuggest_scrapy/AMA_ANALYSIS/USA_analysis.py", line 1198, in USA_second_Analysis
    usa_second_product_obj.Available(sellers_list_url=sellers_list_url,ASIN=ASIN)
  File "/root/Xuggest_scrapy/AMA_ANALYSIS/USA_analysis.py", line 1072, in Available
    etree_html = etree.HTML(sellers_list_responses)
UnboundLocalError: local variable 'sellers_list_responses' referenced before assignment
2018-10-05 04:34:22 [analysis_log] ERROR: into_Sellers_list
Traceback (most recent call last):
  File "/usr/lib/python3/dist-packages/urllib3/connectionpool.py", line 555, in urlopen
    self._prepare_proxy(conn)
  File "/usr/lib/python3/dist-packages/urllib3/connectionpool.py", line 753, in _prepare_proxy
    conn.connect()
  File "/usr/lib/python3/dist-packages/urllib3/connection.py", line 230, in connect
    self._tunnel()
  File "/usr/lib/python3.5/http/client.py", line 827, in _tunnel
    (version, code, message) = response._read_status()
  File "/usr/lib/python3.5/http/client.py", line 258, in _read_status
    line = str(self.fp.readline(_MAXLINE + 1), "iso-8859-1")
  File "/usr/lib/python3.5/socket.py", line 575, in readinto
    return self._sock.recv_into(b)
ConnectionResetError: [Errno 104] Connection reset by peer

During handling of the above exception, another exception occurred:

Traceback (most recent call last):
  File "/usr/lib/python3/dist-packages/requests/adapters.py", line 376, in send
    timeout=timeout
  File "/usr/lib/python3/dist-packages/urllib3/connectionpool.py", line 610, in urlopen
    _stacktrace=sys.exc_info()[2])
  File "/usr/lib/python3/dist-packages/urllib3/util/retry.py", line 273, in increment
    raise MaxRetryError(_pool, url, error or ResponseError(cause))
requests.packages.urllib3.exceptions.MaxRetryError: HTTPSConnectionPool(host='www.amazon.com', port=443): Max retries exceeded with url: /gp/offer-listing/B000MU0K80/ref=dp_olp_new_mbc?ie=UTF8&condition=new (Caused by ProxyError('Cannot connect to proxy.', ConnectionResetError(104, 'Connection reset by peer')))

During handling of the above exception, another exception occurred:

Traceback (most recent call last):
  File "/root/Xuggest_scrapy/AMA_ANALYSIS/analysis_request_header.py", line 300, in into_Sellers_list
    sellers_list_responses = myrequest_get(url=sellers_list_url,headers=headers)
  File "/root/Xuggest_scrapy/AMA_ANALYSIS/analysis_request_header.py", line 256, in myrequest_get
    timeout=20
  File "/usr/lib/python3/dist-packages/requests/api.py", line 67, in get
    return request('get', url, params=params, **kwargs)
  File "/usr/lib/python3/dist-packages/requests/api.py", line 53, in request
    return session.request(method=method, url=url, **kwargs)
  File "/usr/lib/python3/dist-packages/requests/sessions.py", line 468, in request
    resp = self.send(prep, **send_kwargs)
  File "/usr/lib/python3/dist-packages/requests/sessions.py", line 576, in send
    r = adapter.send(request, **kwargs)
  File "/usr/lib/python3/dist-packages/requests/adapters.py", line 437, in send
    raise ConnectionError(e, request=request)
requests.exceptions.ConnectionError: HTTPSConnectionPool(host='www.amazon.com', port=443): Max retries exceeded with url: /gp/offer-listing/B000MU0K80/ref=dp_olp_new_mbc?ie=UTF8&condition=new (Caused by ProxyError('Cannot connect to proxy.', ConnectionResetError(104, 'Connection reset by peer')))
2018-10-05 04:34:22 [analysis_log] ERROR: into_Sellers_list
Traceback (most recent call last):
  File "/usr/lib/python3/dist-packages/urllib3/connectionpool.py", line 555, in urlopen
    self._prepare_proxy(conn)
  File "/usr/lib/python3/dist-packages/urllib3/connectionpool.py", line 753, in _prepare_proxy
    conn.connect()
  File "/usr/lib/python3/dist-packages/urllib3/connection.py", line 230, in connect
    self._tunnel()
  File "/usr/lib/python3.5/http/client.py", line 827, in _tunnel
    (version, code, message) = response._read_status()
  File "/usr/lib/python3.5/http/client.py", line 258, in _read_status
    line = str(self.fp.readline(_MAXLINE + 1), "iso-8859-1")
  File "/usr/lib/python3.5/socket.py", line 575, in readinto
    return self._sock.recv_into(b)
ConnectionResetError: [Errno 104] Connection reset by peer

During handling of the above exception, another exception occurred:

Traceback (most recent call last):
  File "/usr/lib/python3/dist-packages/requests/adapters.py", line 376, in send
    timeout=timeout
  File "/usr/lib/python3/dist-packages/urllib3/connectionpool.py", line 610, in urlopen
    _stacktrace=sys.exc_info()[2])
  File "/usr/lib/python3/dist-packages/urllib3/util/retry.py", line 273, in increment
    raise MaxRetryError(_pool, url, error or ResponseError(cause))
requests.packages.urllib3.exceptions.MaxRetryError: HTTPSConnectionPool(host='www.amazon.com', port=443): Max retries exceeded with url: /gp/offer-listing/B000MU0K80/ref=dp_olp_new_mbc?ie=UTF8&condition=new (Caused by ProxyError('Cannot connect to proxy.', ConnectionResetError(104, 'Connection reset by peer')))

During handling of the above exception, another exception occurred:

Traceback (most recent call last):
  File "/root/Xuggest_scrapy/AMA_ANALYSIS/analysis_request_header.py", line 300, in into_Sellers_list
    sellers_list_responses = myrequest_get(url=sellers_list_url,headers=headers)
  File "/root/Xuggest_scrapy/AMA_ANALYSIS/analysis_request_header.py", line 256, in myrequest_get
    timeout=20
  File "/usr/lib/python3/dist-packages/requests/api.py", line 67, in get
    return request('get', url, params=params, **kwargs)
  File "/usr/lib/python3/dist-packages/requests/api.py", line 53, in request
    return session.request(method=method, url=url, **kwargs)
  File "/usr/lib/python3/dist-packages/requests/sessions.py", line 468, in request
    resp = self.send(prep, **send_kwargs)
  File "/usr/lib/python3/dist-packages/requests/sessions.py", line 576, in send
    r = adapter.send(request, **kwargs)
  File "/usr/lib/python3/dist-packages/requests/adapters.py", line 437, in send
    raise ConnectionError(e, request=request)
requests.exceptions.ConnectionError: HTTPSConnectionPool(host='www.amazon.com', port=443): Max retries exceeded with url: /gp/offer-listing/B000MU0K80/ref=dp_olp_new_mbc?ie=UTF8&condition=new (Caused by ProxyError('Cannot connect to proxy.', ConnectionResetError(104, 'Connection reset by peer')))
2018-10-05 04:34:22 [analysis_log] ERROR: sellers_list_responses
Traceback (most recent call last):
  File "/root/Xuggest_scrapy/AMA_ANALYSIS/USA_analysis.py", line 1067, in Available
    sellers_list_responses = into_Sellers_list(sellers_list_url)
  File "/root/Xuggest_scrapy/AMA_ANALYSIS/analysis_request_header.py", line 305, in into_Sellers_list
    return sellers_list_responses
UnboundLocalError: local variable 'sellers_list_responses' referenced before assignment
2018-10-05 04:34:22 [analysis_log] ERROR: USA_USA_second_Analysis
Traceback (most recent call last):
  File "/root/Xuggest_scrapy/AMA_ANALYSIS/use_analysis.py", line 79, in USA_analysis
    USA_second_Analysis(ASIN=ASIN,stock=Stock,sellers_list_url=sellers_list_url,product_info=product_info,offerListingID=offerListingID)
  File "/root/Xuggest_scrapy/AMA_ANALYSIS/USA_analysis.py", line 1198, in USA_second_Analysis
    usa_second_product_obj.Available(sellers_list_url=sellers_list_url,ASIN=ASIN)
  File "/root/Xuggest_scrapy/AMA_ANALYSIS/USA_analysis.py", line 1072, in Available
    etree_html = etree.HTML(sellers_list_responses)
UnboundLocalError: local variable 'sellers_list_responses' referenced before assignment
2018-10-05 04:34:31 [analysis_log] ERROR: into_Sellers_list
Traceback (most recent call last):
  File "/usr/lib/python3/dist-packages/urllib3/connectionpool.py", line 555, in urlopen
    self._prepare_proxy(conn)
  File "/usr/lib/python3/dist-packages/urllib3/connectionpool.py", line 753, in _prepare_proxy
    conn.connect()
  File "/usr/lib/python3/dist-packages/urllib3/connection.py", line 230, in connect
    self._tunnel()
  File "/usr/lib/python3.5/http/client.py", line 827, in _tunnel
    (version, code, message) = response._read_status()
  File "/usr/lib/python3.5/http/client.py", line 258, in _read_status
    line = str(self.fp.readline(_MAXLINE + 1), "iso-8859-1")
  File "/usr/lib/python3.5/socket.py", line 575, in readinto
    return self._sock.recv_into(b)
ConnectionResetError: [Errno 104] Connection reset by peer

During handling of the above exception, another exception occurred:

Traceback (most recent call last):
  File "/usr/lib/python3/dist-packages/requests/adapters.py", line 376, in send
    timeout=timeout
  File "/usr/lib/python3/dist-packages/urllib3/connectionpool.py", line 610, in urlopen
    _stacktrace=sys.exc_info()[2])
  File "/usr/lib/python3/dist-packages/urllib3/util/retry.py", line 273, in increment
    raise MaxRetryError(_pool, url, error or ResponseError(cause))
requests.packages.urllib3.exceptions.MaxRetryError: HTTPSConnectionPool(host='www.amazon.com', port=443): Max retries exceeded with url: /gp/offer-listing/B00XJOS15A/ref=dp_olp_all_mbc?ie=UTF8&condition=all (Caused by ProxyError('Cannot connect to proxy.', ConnectionResetError(104, 'Connection reset by peer')))

During handling of the above exception, another exception occurred:

Traceback (most recent call last):
  File "/root/Xuggest_scrapy/AMA_ANALYSIS/analysis_request_header.py", line 300, in into_Sellers_list
    sellers_list_responses = myrequest_get(url=sellers_list_url,headers=headers)
  File "/root/Xuggest_scrapy/AMA_ANALYSIS/analysis_request_header.py", line 256, in myrequest_get
    timeout=20
  File "/usr/lib/python3/dist-packages/requests/api.py", line 67, in get
    return request('get', url, params=params, **kwargs)
  File "/usr/lib/python3/dist-packages/requests/api.py", line 53, in request
    return session.request(method=method, url=url, **kwargs)
  File "/usr/lib/python3/dist-packages/requests/sessions.py", line 468, in request
    resp = self.send(prep, **send_kwargs)
  File "/usr/lib/python3/dist-packages/requests/sessions.py", line 576, in send
    r = adapter.send(request, **kwargs)
  File "/usr/lib/python3/dist-packages/requests/adapters.py", line 437, in send
    raise ConnectionError(e, request=request)
requests.exceptions.ConnectionError: HTTPSConnectionPool(host='www.amazon.com', port=443): Max retries exceeded with url: /gp/offer-listing/B00XJOS15A/ref=dp_olp_all_mbc?ie=UTF8&condition=all (Caused by ProxyError('Cannot connect to proxy.', ConnectionResetError(104, 'Connection reset by peer')))
2018-10-05 04:34:32 [analysis_log] ERROR: into_Sellers_list
Traceback (most recent call last):
  File "/usr/lib/python3/dist-packages/urllib3/connectionpool.py", line 555, in urlopen
    self._prepare_proxy(conn)
  File "/usr/lib/python3/dist-packages/urllib3/connectionpool.py", line 753, in _prepare_proxy
    conn.connect()
  File "/usr/lib/python3/dist-packages/urllib3/connection.py", line 230, in connect
    self._tunnel()
  File "/usr/lib/python3.5/http/client.py", line 827, in _tunnel
    (version, code, message) = response._read_status()
  File "/usr/lib/python3.5/http/client.py", line 258, in _read_status
    line = str(self.fp.readline(_MAXLINE + 1), "iso-8859-1")
  File "/usr/lib/python3.5/socket.py", line 575, in readinto
    return self._sock.recv_into(b)
ConnectionResetError: [Errno 104] Connection reset by peer

During handling of the above exception, another exception occurred:

Traceback (most recent call last):
  File "/usr/lib/python3/dist-packages/requests/adapters.py", line 376, in send
    timeout=timeout
  File "/usr/lib/python3/dist-packages/urllib3/connectionpool.py", line 610, in urlopen
    _stacktrace=sys.exc_info()[2])
  File "/usr/lib/python3/dist-packages/urllib3/util/retry.py", line 273, in increment
    raise MaxRetryError(_pool, url, error or ResponseError(cause))
requests.packages.urllib3.exceptions.MaxRetryError: HTTPSConnectionPool(host='www.amazon.com', port=443): Max retries exceeded with url: /gp/offer-listing/B00XJOS15A/ref=dp_olp_all_mbc?ie=UTF8&condition=all (Caused by ProxyError('Cannot connect to proxy.', ConnectionResetError(104, 'Connection reset by peer')))

During handling of the above exception, another exception occurred:

Traceback (most recent call last):
  File "/root/Xuggest_scrapy/AMA_ANALYSIS/analysis_request_header.py", line 300, in into_Sellers_list
    sellers_list_responses = myrequest_get(url=sellers_list_url,headers=headers)
  File "/root/Xuggest_scrapy/AMA_ANALYSIS/analysis_request_header.py", line 256, in myrequest_get
    timeout=20
  File "/usr/lib/python3/dist-packages/requests/api.py", line 67, in get
    return request('get', url, params=params, **kwargs)
  File "/usr/lib/python3/dist-packages/requests/api.py", line 53, in request
    return session.request(method=method, url=url, **kwargs)
  File "/usr/lib/python3/dist-packages/requests/sessions.py", line 468, in request
    resp = self.send(prep, **send_kwargs)
  File "/usr/lib/python3/dist-packages/requests/sessions.py", line 576, in send
    r = adapter.send(request, **kwargs)
  File "/usr/lib/python3/dist-packages/requests/adapters.py", line 437, in send
    raise ConnectionError(e, request=request)
requests.exceptions.ConnectionError: HTTPSConnectionPool(host='www.amazon.com', port=443): Max retries exceeded with url: /gp/offer-listing/B00XJOS15A/ref=dp_olp_all_mbc?ie=UTF8&condition=all (Caused by ProxyError('Cannot connect to proxy.', ConnectionResetError(104, 'Connection reset by peer')))
2018-10-05 04:34:32 [analysis_log] ERROR: sellers_list_responses
Traceback (most recent call last):
  File "/root/Xuggest_scrapy/AMA_ANALYSIS/USA_analysis.py", line 1067, in Available
    sellers_list_responses = into_Sellers_list(sellers_list_url)
  File "/root/Xuggest_scrapy/AMA_ANALYSIS/analysis_request_header.py", line 305, in into_Sellers_list
    return sellers_list_responses
UnboundLocalError: local variable 'sellers_list_responses' referenced before assignment
2018-10-05 04:34:32 [analysis_log] ERROR: USA_USA_second_Analysis
Traceback (most recent call last):
  File "/root/Xuggest_scrapy/AMA_ANALYSIS/use_analysis.py", line 79, in USA_analysis
    USA_second_Analysis(ASIN=ASIN,stock=Stock,sellers_list_url=sellers_list_url,product_info=product_info,offerListingID=offerListingID)
  File "/root/Xuggest_scrapy/AMA_ANALYSIS/USA_analysis.py", line 1198, in USA_second_Analysis
    usa_second_product_obj.Available(sellers_list_url=sellers_list_url,ASIN=ASIN)
  File "/root/Xuggest_scrapy/AMA_ANALYSIS/USA_analysis.py", line 1072, in Available
    etree_html = etree.HTML(sellers_list_responses)
UnboundLocalError: local variable 'sellers_list_responses' referenced before assignment
2018-10-05 04:34:42 [analysis_log] ERROR: into_Sellers_list
Traceback (most recent call last):
  File "/usr/lib/python3/dist-packages/urllib3/connectionpool.py", line 555, in urlopen
    self._prepare_proxy(conn)
  File "/usr/lib/python3/dist-packages/urllib3/connectionpool.py", line 753, in _prepare_proxy
    conn.connect()
  File "/usr/lib/python3/dist-packages/urllib3/connection.py", line 230, in connect
    self._tunnel()
  File "/usr/lib/python3.5/http/client.py", line 827, in _tunnel
    (version, code, message) = response._read_status()
  File "/usr/lib/python3.5/http/client.py", line 258, in _read_status
    line = str(self.fp.readline(_MAXLINE + 1), "iso-8859-1")
  File "/usr/lib/python3.5/socket.py", line 575, in readinto
    return self._sock.recv_into(b)
ConnectionResetError: [Errno 104] Connection reset by peer

During handling of the above exception, another exception occurred:

Traceback (most recent call last):
  File "/usr/lib/python3/dist-packages/requests/adapters.py", line 376, in send
    timeout=timeout
  File "/usr/lib/python3/dist-packages/urllib3/connectionpool.py", line 610, in urlopen
    _stacktrace=sys.exc_info()[2])
  File "/usr/lib/python3/dist-packages/urllib3/util/retry.py", line 273, in increment
    raise MaxRetryError(_pool, url, error or ResponseError(cause))
requests.packages.urllib3.exceptions.MaxRetryError: HTTPSConnectionPool(host='www.amazon.com', port=443): Max retries exceeded with url: /gp/offer-listing/B004OA7LJU/ref=dp_olp_new_mbc?ie=UTF8&condition=new (Caused by ProxyError('Cannot connect to proxy.', ConnectionResetError(104, 'Connection reset by peer')))

During handling of the above exception, another exception occurred:

Traceback (most recent call last):
  File "/root/Xuggest_scrapy/AMA_ANALYSIS/analysis_request_header.py", line 300, in into_Sellers_list
    sellers_list_responses = myrequest_get(url=sellers_list_url,headers=headers)
  File "/root/Xuggest_scrapy/AMA_ANALYSIS/analysis_request_header.py", line 256, in myrequest_get
    timeout=20
  File "/usr/lib/python3/dist-packages/requests/api.py", line 67, in get
    return request('get', url, params=params, **kwargs)
  File "/usr/lib/python3/dist-packages/requests/api.py", line 53, in request
    return session.request(method=method, url=url, **kwargs)
  File "/usr/lib/python3/dist-packages/requests/sessions.py", line 468, in request
    resp = self.send(prep, **send_kwargs)
  File "/usr/lib/python3/dist-packages/requests/sessions.py", line 576, in send
    r = adapter.send(request, **kwargs)
  File "/usr/lib/python3/dist-packages/requests/adapters.py", line 437, in send
    raise ConnectionError(e, request=request)
requests.exceptions.ConnectionError: HTTPSConnectionPool(host='www.amazon.com', port=443): Max retries exceeded with url: /gp/offer-listing/B004OA7LJU/ref=dp_olp_new_mbc?ie=UTF8&condition=new (Caused by ProxyError('Cannot connect to proxy.', ConnectionResetError(104, 'Connection reset by peer')))
2018-10-05 04:34:43 [analysis_log] ERROR: into_Sellers_list
Traceback (most recent call last):
  File "/usr/lib/python3/dist-packages/urllib3/connectionpool.py", line 555, in urlopen
    self._prepare_proxy(conn)
  File "/usr/lib/python3/dist-packages/urllib3/connectionpool.py", line 753, in _prepare_proxy
    conn.connect()
  File "/usr/lib/python3/dist-packages/urllib3/connection.py", line 230, in connect
    self._tunnel()
  File "/usr/lib/python3.5/http/client.py", line 827, in _tunnel
    (version, code, message) = response._read_status()
  File "/usr/lib/python3.5/http/client.py", line 258, in _read_status
    line = str(self.fp.readline(_MAXLINE + 1), "iso-8859-1")
  File "/usr/lib/python3.5/socket.py", line 575, in readinto
    return self._sock.recv_into(b)
ConnectionResetError: [Errno 104] Connection reset by peer

During handling of the above exception, another exception occurred:

Traceback (most recent call last):
  File "/usr/lib/python3/dist-packages/requests/adapters.py", line 376, in send
    timeout=timeout
  File "/usr/lib/python3/dist-packages/urllib3/connectionpool.py", line 610, in urlopen
    _stacktrace=sys.exc_info()[2])
  File "/usr/lib/python3/dist-packages/urllib3/util/retry.py", line 273, in increment
    raise MaxRetryError(_pool, url, error or ResponseError(cause))
requests.packages.urllib3.exceptions.MaxRetryError: HTTPSConnectionPool(host='www.amazon.com', port=443): Max retries exceeded with url: /gp/offer-listing/B004OA7LJU/ref=dp_olp_new_mbc?ie=UTF8&condition=new (Caused by ProxyError('Cannot connect to proxy.', ConnectionResetError(104, 'Connection reset by peer')))

During handling of the above exception, another exception occurred:

Traceback (most recent call last):
  File "/root/Xuggest_scrapy/AMA_ANALYSIS/analysis_request_header.py", line 300, in into_Sellers_list
    sellers_list_responses = myrequest_get(url=sellers_list_url,headers=headers)
  File "/root/Xuggest_scrapy/AMA_ANALYSIS/analysis_request_header.py", line 256, in myrequest_get
    timeout=20
  File "/usr/lib/python3/dist-packages/requests/api.py", line 67, in get
    return request('get', url, params=params, **kwargs)
  File "/usr/lib/python3/dist-packages/requests/api.py", line 53, in request
    return session.request(method=method, url=url, **kwargs)
  File "/usr/lib/python3/dist-packages/requests/sessions.py", line 468, in request
    resp = self.send(prep, **send_kwargs)
  File "/usr/lib/python3/dist-packages/requests/sessions.py", line 576, in send
    r = adapter.send(request, **kwargs)
  File "/usr/lib/python3/dist-packages/requests/adapters.py", line 437, in send
    raise ConnectionError(e, request=request)
requests.exceptions.ConnectionError: HTTPSConnectionPool(host='www.amazon.com', port=443): Max retries exceeded with url: /gp/offer-listing/B004OA7LJU/ref=dp_olp_new_mbc?ie=UTF8&condition=new (Caused by ProxyError('Cannot connect to proxy.', ConnectionResetError(104, 'Connection reset by peer')))
2018-10-05 04:34:43 [analysis_log] ERROR: sellers_list_responses
Traceback (most recent call last):
  File "/root/Xuggest_scrapy/AMA_ANALYSIS/USA_analysis.py", line 1067, in Available
    sellers_list_responses = into_Sellers_list(sellers_list_url)
  File "/root/Xuggest_scrapy/AMA_ANALYSIS/analysis_request_header.py", line 305, in into_Sellers_list
    return sellers_list_responses
UnboundLocalError: local variable 'sellers_list_responses' referenced before assignment
2018-10-05 04:34:43 [analysis_log] ERROR: USA_USA_second_Analysis
Traceback (most recent call last):
  File "/root/Xuggest_scrapy/AMA_ANALYSIS/use_analysis.py", line 79, in USA_analysis
    USA_second_Analysis(ASIN=ASIN,stock=Stock,sellers_list_url=sellers_list_url,product_info=product_info,offerListingID=offerListingID)
  File "/root/Xuggest_scrapy/AMA_ANALYSIS/USA_analysis.py", line 1198, in USA_second_Analysis
    usa_second_product_obj.Available(sellers_list_url=sellers_list_url,ASIN=ASIN)
  File "/root/Xuggest_scrapy/AMA_ANALYSIS/USA_analysis.py", line 1072, in Available
    etree_html = etree.HTML(sellers_list_responses)
UnboundLocalError: local variable 'sellers_list_responses' referenced before assignment
2018-10-05 04:35:23 [analysis_log] ERROR: into_Sellers_list
Traceback (most recent call last):
  File "/usr/lib/python3/dist-packages/urllib3/connectionpool.py", line 555, in urlopen
    self._prepare_proxy(conn)
  File "/usr/lib/python3/dist-packages/urllib3/connectionpool.py", line 753, in _prepare_proxy
    conn.connect()
  File "/usr/lib/python3/dist-packages/urllib3/connection.py", line 230, in connect
    self._tunnel()
  File "/usr/lib/python3.5/http/client.py", line 827, in _tunnel
    (version, code, message) = response._read_status()
  File "/usr/lib/python3.5/http/client.py", line 258, in _read_status
    line = str(self.fp.readline(_MAXLINE + 1), "iso-8859-1")
  File "/usr/lib/python3.5/socket.py", line 575, in readinto
    return self._sock.recv_into(b)
ConnectionResetError: [Errno 104] Connection reset by peer

During handling of the above exception, another exception occurred:

Traceback (most recent call last):
  File "/usr/lib/python3/dist-packages/requests/adapters.py", line 376, in send
    timeout=timeout
  File "/usr/lib/python3/dist-packages/urllib3/connectionpool.py", line 610, in urlopen
    _stacktrace=sys.exc_info()[2])
  File "/usr/lib/python3/dist-packages/urllib3/util/retry.py", line 273, in increment
    raise MaxRetryError(_pool, url, error or ResponseError(cause))
requests.packages.urllib3.exceptions.MaxRetryError: HTTPSConnectionPool(host='www.amazon.com', port=443): Max retries exceeded with url: /gp/offer-listing/B0180UVGZE/ref=dp_olp_new_mbc?ie=UTF8&condition=new (Caused by ProxyError('Cannot connect to proxy.', ConnectionResetError(104, 'Connection reset by peer')))

During handling of the above exception, another exception occurred:

Traceback (most recent call last):
  File "/root/Xuggest_scrapy/AMA_ANALYSIS/analysis_request_header.py", line 300, in into_Sellers_list
    sellers_list_responses = myrequest_get(url=sellers_list_url,headers=headers)
  File "/root/Xuggest_scrapy/AMA_ANALYSIS/analysis_request_header.py", line 256, in myrequest_get
    timeout=20
  File "/usr/lib/python3/dist-packages/requests/api.py", line 67, in get
    return request('get', url, params=params, **kwargs)
  File "/usr/lib/python3/dist-packages/requests/api.py", line 53, in request
    return session.request(method=method, url=url, **kwargs)
  File "/usr/lib/python3/dist-packages/requests/sessions.py", line 468, in request
    resp = self.send(prep, **send_kwargs)
  File "/usr/lib/python3/dist-packages/requests/sessions.py", line 576, in send
    r = adapter.send(request, **kwargs)
  File "/usr/lib/python3/dist-packages/requests/adapters.py", line 437, in send
    raise ConnectionError(e, request=request)
requests.exceptions.ConnectionError: HTTPSConnectionPool(host='www.amazon.com', port=443): Max retries exceeded with url: /gp/offer-listing/B0180UVGZE/ref=dp_olp_new_mbc?ie=UTF8&condition=new (Caused by ProxyError('Cannot connect to proxy.', ConnectionResetError(104, 'Connection reset by peer')))
2018-10-05 04:35:24 [analysis_log] ERROR: into_Sellers_list
Traceback (most recent call last):
  File "/usr/lib/python3/dist-packages/urllib3/connectionpool.py", line 555, in urlopen
    self._prepare_proxy(conn)
  File "/usr/lib/python3/dist-packages/urllib3/connectionpool.py", line 753, in _prepare_proxy
    conn.connect()
  File "/usr/lib/python3/dist-packages/urllib3/connection.py", line 230, in connect
    self._tunnel()
  File "/usr/lib/python3.5/http/client.py", line 827, in _tunnel
    (version, code, message) = response._read_status()
  File "/usr/lib/python3.5/http/client.py", line 258, in _read_status
    line = str(self.fp.readline(_MAXLINE + 1), "iso-8859-1")
  File "/usr/lib/python3.5/socket.py", line 575, in readinto
    return self._sock.recv_into(b)
ConnectionResetError: [Errno 104] Connection reset by peer

During handling of the above exception, another exception occurred:

Traceback (most recent call last):
  File "/usr/lib/python3/dist-packages/requests/adapters.py", line 376, in send
    timeout=timeout
  File "/usr/lib/python3/dist-packages/urllib3/connectionpool.py", line 610, in urlopen
    _stacktrace=sys.exc_info()[2])
  File "/usr/lib/python3/dist-packages/urllib3/util/retry.py", line 273, in increment
    raise MaxRetryError(_pool, url, error or ResponseError(cause))
requests.packages.urllib3.exceptions.MaxRetryError: HTTPSConnectionPool(host='www.amazon.com', port=443): Max retries exceeded with url: /gp/offer-listing/B0180UVGZE/ref=dp_olp_new_mbc?ie=UTF8&condition=new (Caused by ProxyError('Cannot connect to proxy.', ConnectionResetError(104, 'Connection reset by peer')))

During handling of the above exception, another exception occurred:

Traceback (most recent call last):
  File "/root/Xuggest_scrapy/AMA_ANALYSIS/analysis_request_header.py", line 300, in into_Sellers_list
    sellers_list_responses = myrequest_get(url=sellers_list_url,headers=headers)
  File "/root/Xuggest_scrapy/AMA_ANALYSIS/analysis_request_header.py", line 256, in myrequest_get
    timeout=20
  File "/usr/lib/python3/dist-packages/requests/api.py", line 67, in get
    return request('get', url, params=params, **kwargs)
  File "/usr/lib/python3/dist-packages/requests/api.py", line 53, in request
    return session.request(method=method, url=url, **kwargs)
  File "/usr/lib/python3/dist-packages/requests/sessions.py", line 468, in request
    resp = self.send(prep, **send_kwargs)
  File "/usr/lib/python3/dist-packages/requests/sessions.py", line 576, in send
    r = adapter.send(request, **kwargs)
  File "/usr/lib/python3/dist-packages/requests/adapters.py", line 437, in send
    raise ConnectionError(e, request=request)
requests.exceptions.ConnectionError: HTTPSConnectionPool(host='www.amazon.com', port=443): Max retries exceeded with url: /gp/offer-listing/B0180UVGZE/ref=dp_olp_new_mbc?ie=UTF8&condition=new (Caused by ProxyError('Cannot connect to proxy.', ConnectionResetError(104, 'Connection reset by peer')))
2018-10-05 04:35:24 [analysis_log] ERROR: sellers_list_responses
Traceback (most recent call last):
  File "/root/Xuggest_scrapy/AMA_ANALYSIS/USA_analysis.py", line 1067, in Available
    sellers_list_responses = into_Sellers_list(sellers_list_url)
  File "/root/Xuggest_scrapy/AMA_ANALYSIS/analysis_request_header.py", line 305, in into_Sellers_list
    return sellers_list_responses
UnboundLocalError: local variable 'sellers_list_responses' referenced before assignment
2018-10-05 04:35:24 [analysis_log] ERROR: USA_USA_second_Analysis
Traceback (most recent call last):
  File "/root/Xuggest_scrapy/AMA_ANALYSIS/use_analysis.py", line 79, in USA_analysis
    USA_second_Analysis(ASIN=ASIN,stock=Stock,sellers_list_url=sellers_list_url,product_info=product_info,offerListingID=offerListingID)
  File "/root/Xuggest_scrapy/AMA_ANALYSIS/USA_analysis.py", line 1198, in USA_second_Analysis
    usa_second_product_obj.Available(sellers_list_url=sellers_list_url,ASIN=ASIN)
  File "/root/Xuggest_scrapy/AMA_ANALYSIS/USA_analysis.py", line 1072, in Available
    etree_html = etree.HTML(sellers_list_responses)
UnboundLocalError: local variable 'sellers_list_responses' referenced before assignment
2018-10-05 04:35:36 [analysis_log] ERROR: into_Sellers_list
Traceback (most recent call last):
  File "/usr/lib/python3/dist-packages/urllib3/connectionpool.py", line 555, in urlopen
    self._prepare_proxy(conn)
  File "/usr/lib/python3/dist-packages/urllib3/connectionpool.py", line 753, in _prepare_proxy
    conn.connect()
  File "/usr/lib/python3/dist-packages/urllib3/connection.py", line 230, in connect
    self._tunnel()
  File "/usr/lib/python3.5/http/client.py", line 827, in _tunnel
    (version, code, message) = response._read_status()
  File "/usr/lib/python3.5/http/client.py", line 258, in _read_status
    line = str(self.fp.readline(_MAXLINE + 1), "iso-8859-1")
  File "/usr/lib/python3.5/socket.py", line 575, in readinto
    return self._sock.recv_into(b)
ConnectionResetError: [Errno 104] Connection reset by peer

During handling of the above exception, another exception occurred:

Traceback (most recent call last):
  File "/usr/lib/python3/dist-packages/requests/adapters.py", line 376, in send
    timeout=timeout
  File "/usr/lib/python3/dist-packages/urllib3/connectionpool.py", line 610, in urlopen
    _stacktrace=sys.exc_info()[2])
  File "/usr/lib/python3/dist-packages/urllib3/util/retry.py", line 273, in increment
    raise MaxRetryError(_pool, url, error or ResponseError(cause))
requests.packages.urllib3.exceptions.MaxRetryError: HTTPSConnectionPool(host='www.amazon.com', port=443): Max retries exceeded with url: /gp/offer-listing/B00FOWQUZS/ref=dp_olp_all_mbc?ie=UTF8&condition=all (Caused by ProxyError('Cannot connect to proxy.', ConnectionResetError(104, 'Connection reset by peer')))

During handling of the above exception, another exception occurred:

Traceback (most recent call last):
  File "/root/Xuggest_scrapy/AMA_ANALYSIS/analysis_request_header.py", line 300, in into_Sellers_list
    sellers_list_responses = myrequest_get(url=sellers_list_url,headers=headers)
  File "/root/Xuggest_scrapy/AMA_ANALYSIS/analysis_request_header.py", line 256, in myrequest_get
    timeout=20
  File "/usr/lib/python3/dist-packages/requests/api.py", line 67, in get
    return request('get', url, params=params, **kwargs)
  File "/usr/lib/python3/dist-packages/requests/api.py", line 53, in request
    return session.request(method=method, url=url, **kwargs)
  File "/usr/lib/python3/dist-packages/requests/sessions.py", line 468, in request
    resp = self.send(prep, **send_kwargs)
  File "/usr/lib/python3/dist-packages/requests/sessions.py", line 576, in send
    r = adapter.send(request, **kwargs)
  File "/usr/lib/python3/dist-packages/requests/adapters.py", line 437, in send
    raise ConnectionError(e, request=request)
requests.exceptions.ConnectionError: HTTPSConnectionPool(host='www.amazon.com', port=443): Max retries exceeded with url: /gp/offer-listing/B00FOWQUZS/ref=dp_olp_all_mbc?ie=UTF8&condition=all (Caused by ProxyError('Cannot connect to proxy.', ConnectionResetError(104, 'Connection reset by peer')))
2018-10-05 04:35:36 [analysis_log] ERROR: into_Sellers_list
Traceback (most recent call last):
  File "/usr/lib/python3/dist-packages/urllib3/connectionpool.py", line 555, in urlopen
    self._prepare_proxy(conn)
  File "/usr/lib/python3/dist-packages/urllib3/connectionpool.py", line 753, in _prepare_proxy
    conn.connect()
  File "/usr/lib/python3/dist-packages/urllib3/connection.py", line 230, in connect
    self._tunnel()
  File "/usr/lib/python3.5/http/client.py", line 827, in _tunnel
    (version, code, message) = response._read_status()
  File "/usr/lib/python3.5/http/client.py", line 258, in _read_status
    line = str(self.fp.readline(_MAXLINE + 1), "iso-8859-1")
  File "/usr/lib/python3.5/socket.py", line 575, in readinto
    return self._sock.recv_into(b)
ConnectionResetError: [Errno 104] Connection reset by peer

During handling of the above exception, another exception occurred:

Traceback (most recent call last):
  File "/usr/lib/python3/dist-packages/requests/adapters.py", line 376, in send
    timeout=timeout
  File "/usr/lib/python3/dist-packages/urllib3/connectionpool.py", line 610, in urlopen
    _stacktrace=sys.exc_info()[2])
  File "/usr/lib/python3/dist-packages/urllib3/util/retry.py", line 273, in increment
    raise MaxRetryError(_pool, url, error or ResponseError(cause))
requests.packages.urllib3.exceptions.MaxRetryError: HTTPSConnectionPool(host='www.amazon.com', port=443): Max retries exceeded with url: /gp/offer-listing/B00FOWQUZS/ref=dp_olp_all_mbc?ie=UTF8&condition=all (Caused by ProxyError('Cannot connect to proxy.', ConnectionResetError(104, 'Connection reset by peer')))

During handling of the above exception, another exception occurred:

Traceback (most recent call last):
  File "/root/Xuggest_scrapy/AMA_ANALYSIS/analysis_request_header.py", line 300, in into_Sellers_list
    sellers_list_responses = myrequest_get(url=sellers_list_url,headers=headers)
  File "/root/Xuggest_scrapy/AMA_ANALYSIS/analysis_request_header.py", line 256, in myrequest_get
    timeout=20
  File "/usr/lib/python3/dist-packages/requests/api.py", line 67, in get
    return request('get', url, params=params, **kwargs)
  File "/usr/lib/python3/dist-packages/requests/api.py", line 53, in request
    return session.request(method=method, url=url, **kwargs)
  File "/usr/lib/python3/dist-packages/requests/sessions.py", line 468, in request
    resp = self.send(prep, **send_kwargs)
  File "/usr/lib/python3/dist-packages/requests/sessions.py", line 576, in send
    r = adapter.send(request, **kwargs)
  File "/usr/lib/python3/dist-packages/requests/adapters.py", line 437, in send
    raise ConnectionError(e, request=request)
requests.exceptions.ConnectionError: HTTPSConnectionPool(host='www.amazon.com', port=443): Max retries exceeded with url: /gp/offer-listing/B00FOWQUZS/ref=dp_olp_all_mbc?ie=UTF8&condition=all (Caused by ProxyError('Cannot connect to proxy.', ConnectionResetError(104, 'Connection reset by peer')))
2018-10-05 04:35:36 [analysis_log] ERROR: sellers_list_responses
Traceback (most recent call last):
  File "/root/Xuggest_scrapy/AMA_ANALYSIS/USA_analysis.py", line 1067, in Available
    sellers_list_responses = into_Sellers_list(sellers_list_url)
  File "/root/Xuggest_scrapy/AMA_ANALYSIS/analysis_request_header.py", line 305, in into_Sellers_list
    return sellers_list_responses
UnboundLocalError: local variable 'sellers_list_responses' referenced before assignment
2018-10-05 04:35:36 [analysis_log] ERROR: USA_USA_second_Analysis
Traceback (most recent call last):
  File "/root/Xuggest_scrapy/AMA_ANALYSIS/use_analysis.py", line 79, in USA_analysis
    USA_second_Analysis(ASIN=ASIN,stock=Stock,sellers_list_url=sellers_list_url,product_info=product_info,offerListingID=offerListingID)
  File "/root/Xuggest_scrapy/AMA_ANALYSIS/USA_analysis.py", line 1198, in USA_second_Analysis
    usa_second_product_obj.Available(sellers_list_url=sellers_list_url,ASIN=ASIN)
  File "/root/Xuggest_scrapy/AMA_ANALYSIS/USA_analysis.py", line 1072, in Available
    etree_html = etree.HTML(sellers_list_responses)
UnboundLocalError: local variable 'sellers_list_responses' referenced before assignment
2018-10-05 04:36:26 [root] WARNING: 重复处理：https://www.amazon.com/UONQD-Letter-Blouse-Sleeve-Patchwork/dp/B07FY164X8/ref=zg_bs_12896841_93?_encoding=UTF8&refRID=H1M2C4K54SNBMJBH1VFS
2018-10-05 04:37:05 [root] WARNING: 重复处理：https://www.amazon.com/Clearance-Seaintheson-Women-Pullover-Tops/dp/B07GKPJLQ5/ref=zg_bs_12897421_88?_encoding=UTF8&refRID=RGNDKB95T72MT398CTK0
2018-10-05 04:37:08 [root] WARNING: 重复处理：https://www.amazon.com/SMALLE%E2%97%95%E2%80%BF%E2%97%95-Clearance-Newborn-Camouflage-Jumpsuit/dp/B07F38PP82/ref=zg_bs_12896781_45?_encoding=UTF8&refRID=NNZPVP36DZP2A66H5GN1
2018-10-05 04:37:22 [root] WARNING: 重复处理：https://www.amazon.com/Craftsmart-Fine-Line-Paint-Pens/dp/B06XK9NMTD/ref=zg_bs_12896661_84?_encoding=UTF8&psc=1&refRID=HYDJSDG2A6ZEBYC0XYZ5
2018-10-05 04:38:26 [root] WARNING: 重复处理：https://www.amazon.com/ALEX-DIY-Friends-Ever-Scrapbook/dp/B00HYW4IHI/ref=zg_bs_8090717011_76?_encoding=UTF8&psc=1&refRID=Y2TVDZ2A2NVWDE5N1M53
2018-10-05 04:38:45 [root] WARNING: 重复处理：https://www.amazon.com/Easonove-Alphabet-Painting-Scrapbook-Journaling/dp/B077RVFQ3S/ref=zg_bs_12898101_95?_encoding=UTF8&psc=1&refRID=8W70AGNVTK2DQXGZYN94
2018-10-05 04:38:48 [root] WARNING: 重复处理：https://www.amazon.com/Attisstore-Stencils-Marking-Commercial-Interlocking/dp/B07C6W7BVM/ref=zg_bs_12898101_72?_encoding=UTF8&psc=1&refRID=8W70AGNVTK2DQXGZYN94
2018-10-05 04:38:54 [root] WARNING: 重复处理：https://www.amazon.com/Paint-Glass-Ceramic-Stone-Painting/dp/B07FZ4SM82/ref=zg_bs_8090719011_47?_encoding=UTF8&psc=1&refRID=0JY9RT7V54MKY8D2Y1Q2
2018-10-05 04:39:36 [root] WARNING: 重复处理：https://www.amazon.com/EK-Success-Brands-Decorative-Traveling/dp/B00B1PB2SM/ref=zg_bs_12898951_92?_encoding=UTF8&psc=1&refRID=B010KDV8WF0KYAHQDME5
2018-10-05 04:39:40 [analysis_log] ERROR: into_Sellers_list
Traceback (most recent call last):
  File "/usr/lib/python3/dist-packages/urllib3/connectionpool.py", line 555, in urlopen
    self._prepare_proxy(conn)
  File "/usr/lib/python3/dist-packages/urllib3/connectionpool.py", line 753, in _prepare_proxy
    conn.connect()
  File "/usr/lib/python3/dist-packages/urllib3/connection.py", line 230, in connect
    self._tunnel()
  File "/usr/lib/python3.5/http/client.py", line 827, in _tunnel
    (version, code, message) = response._read_status()
  File "/usr/lib/python3.5/http/client.py", line 258, in _read_status
    line = str(self.fp.readline(_MAXLINE + 1), "iso-8859-1")
  File "/usr/lib/python3.5/socket.py", line 575, in readinto
    return self._sock.recv_into(b)
ConnectionResetError: [Errno 104] Connection reset by peer

During handling of the above exception, another exception occurred:

Traceback (most recent call last):
  File "/usr/lib/python3/dist-packages/requests/adapters.py", line 376, in send
    timeout=timeout
  File "/usr/lib/python3/dist-packages/urllib3/connectionpool.py", line 610, in urlopen
    _stacktrace=sys.exc_info()[2])
  File "/usr/lib/python3/dist-packages/urllib3/util/retry.py", line 273, in increment
    raise MaxRetryError(_pool, url, error or ResponseError(cause))
requests.packages.urllib3.exceptions.MaxRetryError: HTTPSConnectionPool(host='www.amazon.com', port=443): Max retries exceeded with url: /gp/offer-listing/B0086P5JWK/ref=dp_olp_new_mbc?ie=UTF8&condition=new (Caused by ProxyError('Cannot connect to proxy.', ConnectionResetError(104, 'Connection reset by peer')))

During handling of the above exception, another exception occurred:

Traceback (most recent call last):
  File "/root/Xuggest_scrapy/AMA_ANALYSIS/analysis_request_header.py", line 300, in into_Sellers_list
    sellers_list_responses = myrequest_get(url=sellers_list_url,headers=headers)
  File "/root/Xuggest_scrapy/AMA_ANALYSIS/analysis_request_header.py", line 256, in myrequest_get
    timeout=20
  File "/usr/lib/python3/dist-packages/requests/api.py", line 67, in get
    return request('get', url, params=params, **kwargs)
  File "/usr/lib/python3/dist-packages/requests/api.py", line 53, in request
    return session.request(method=method, url=url, **kwargs)
  File "/usr/lib/python3/dist-packages/requests/sessions.py", line 468, in request
    resp = self.send(prep, **send_kwargs)
  File "/usr/lib/python3/dist-packages/requests/sessions.py", line 576, in send
    r = adapter.send(request, **kwargs)
  File "/usr/lib/python3/dist-packages/requests/adapters.py", line 437, in send
    raise ConnectionError(e, request=request)
requests.exceptions.ConnectionError: HTTPSConnectionPool(host='www.amazon.com', port=443): Max retries exceeded with url: /gp/offer-listing/B0086P5JWK/ref=dp_olp_new_mbc?ie=UTF8&condition=new (Caused by ProxyError('Cannot connect to proxy.', ConnectionResetError(104, 'Connection reset by peer')))
2018-10-05 04:39:41 [analysis_log] ERROR: into_Sellers_list
Traceback (most recent call last):
  File "/usr/lib/python3/dist-packages/urllib3/connectionpool.py", line 555, in urlopen
    self._prepare_proxy(conn)
  File "/usr/lib/python3/dist-packages/urllib3/connectionpool.py", line 753, in _prepare_proxy
    conn.connect()
  File "/usr/lib/python3/dist-packages/urllib3/connection.py", line 230, in connect
    self._tunnel()
  File "/usr/lib/python3.5/http/client.py", line 827, in _tunnel
    (version, code, message) = response._read_status()
  File "/usr/lib/python3.5/http/client.py", line 258, in _read_status
    line = str(self.fp.readline(_MAXLINE + 1), "iso-8859-1")
  File "/usr/lib/python3.5/socket.py", line 575, in readinto
    return self._sock.recv_into(b)
ConnectionResetError: [Errno 104] Connection reset by peer

During handling of the above exception, another exception occurred:

Traceback (most recent call last):
  File "/usr/lib/python3/dist-packages/requests/adapters.py", line 376, in send
    timeout=timeout
  File "/usr/lib/python3/dist-packages/urllib3/connectionpool.py", line 610, in urlopen
    _stacktrace=sys.exc_info()[2])
  File "/usr/lib/python3/dist-packages/urllib3/util/retry.py", line 273, in increment
    raise MaxRetryError(_pool, url, error or ResponseError(cause))
requests.packages.urllib3.exceptions.MaxRetryError: HTTPSConnectionPool(host='www.amazon.com', port=443): Max retries exceeded with url: /gp/offer-listing/B0086P5JWK/ref=dp_olp_new_mbc?ie=UTF8&condition=new (Caused by ProxyError('Cannot connect to proxy.', ConnectionResetError(104, 'Connection reset by peer')))

During handling of the above exception, another exception occurred:

Traceback (most recent call last):
  File "/root/Xuggest_scrapy/AMA_ANALYSIS/analysis_request_header.py", line 300, in into_Sellers_list
    sellers_list_responses = myrequest_get(url=sellers_list_url,headers=headers)
  File "/root/Xuggest_scrapy/AMA_ANALYSIS/analysis_request_header.py", line 256, in myrequest_get
    timeout=20
  File "/usr/lib/python3/dist-packages/requests/api.py", line 67, in get
    return request('get', url, params=params, **kwargs)
  File "/usr/lib/python3/dist-packages/requests/api.py", line 53, in request
    return session.request(method=method, url=url, **kwargs)
  File "/usr/lib/python3/dist-packages/requests/sessions.py", line 468, in request
    resp = self.send(prep, **send_kwargs)
  File "/usr/lib/python3/dist-packages/requests/sessions.py", line 576, in send
    r = adapter.send(request, **kwargs)
  File "/usr/lib/python3/dist-packages/requests/adapters.py", line 437, in send
    raise ConnectionError(e, request=request)
requests.exceptions.ConnectionError: HTTPSConnectionPool(host='www.amazon.com', port=443): Max retries exceeded with url: /gp/offer-listing/B0086P5JWK/ref=dp_olp_new_mbc?ie=UTF8&condition=new (Caused by ProxyError('Cannot connect to proxy.', ConnectionResetError(104, 'Connection reset by peer')))
2018-10-05 04:39:41 [analysis_log] ERROR: sellers_list_responses
Traceback (most recent call last):
  File "/root/Xuggest_scrapy/AMA_ANALYSIS/USA_analysis.py", line 1067, in Available
    sellers_list_responses = into_Sellers_list(sellers_list_url)
  File "/root/Xuggest_scrapy/AMA_ANALYSIS/analysis_request_header.py", line 305, in into_Sellers_list
    return sellers_list_responses
UnboundLocalError: local variable 'sellers_list_responses' referenced before assignment
2018-10-05 04:39:41 [analysis_log] ERROR: USA_USA_second_Analysis
Traceback (most recent call last):
  File "/root/Xuggest_scrapy/AMA_ANALYSIS/use_analysis.py", line 79, in USA_analysis
    USA_second_Analysis(ASIN=ASIN,stock=Stock,sellers_list_url=sellers_list_url,product_info=product_info,offerListingID=offerListingID)
  File "/root/Xuggest_scrapy/AMA_ANALYSIS/USA_analysis.py", line 1198, in USA_second_Analysis
    usa_second_product_obj.Available(sellers_list_url=sellers_list_url,ASIN=ASIN)
  File "/root/Xuggest_scrapy/AMA_ANALYSIS/USA_analysis.py", line 1072, in Available
    etree_html = etree.HTML(sellers_list_responses)
UnboundLocalError: local variable 'sellers_list_responses' referenced before assignment
2018-10-05 04:39:47 [root] WARNING: 重复处理：https://www.amazon.com/Yescom-Digital-Sublimation-Transfer-Machine/dp/B01078NG1O/ref=zg_bs_8090715011_82?_encoding=UTF8&psc=1&refRID=FQ541X2MEA87367KHFQY
2018-10-05 04:39:48 [root] WARNING: 重复处理：https://www.amazon.com/CO-Z-Degree-Machine-Multifunction-Sublimation/dp/B077ZMR5H2/ref=zg_bs_8090715011_52?_encoding=UTF8&psc=1&refRID=FQ541X2MEA87367KHFQY
2018-10-05 04:40:31 [analysis_log] ERROR: into_Sellers_list
Traceback (most recent call last):
  File "/usr/lib/python3/dist-packages/urllib3/connectionpool.py", line 555, in urlopen
    self._prepare_proxy(conn)
  File "/usr/lib/python3/dist-packages/urllib3/connectionpool.py", line 753, in _prepare_proxy
    conn.connect()
  File "/usr/lib/python3/dist-packages/urllib3/connection.py", line 230, in connect
    self._tunnel()
  File "/usr/lib/python3.5/http/client.py", line 827, in _tunnel
    (version, code, message) = response._read_status()
  File "/usr/lib/python3.5/http/client.py", line 258, in _read_status
    line = str(self.fp.readline(_MAXLINE + 1), "iso-8859-1")
  File "/usr/lib/python3.5/socket.py", line 575, in readinto
    return self._sock.recv_into(b)
ConnectionResetError: [Errno 104] Connection reset by peer

During handling of the above exception, another exception occurred:

Traceback (most recent call last):
  File "/usr/lib/python3/dist-packages/requests/adapters.py", line 376, in send
    timeout=timeout
  File "/usr/lib/python3/dist-packages/urllib3/connectionpool.py", line 610, in urlopen
    _stacktrace=sys.exc_info()[2])
  File "/usr/lib/python3/dist-packages/urllib3/util/retry.py", line 273, in increment
    raise MaxRetryError(_pool, url, error or ResponseError(cause))
requests.packages.urllib3.exceptions.MaxRetryError: HTTPSConnectionPool(host='www.amazon.com', port=443): Max retries exceeded with url: /gp/offer-listing/B0779MJ1P5/ref=dp_olp_new_mbc?ie=UTF8&condition=new (Caused by ProxyError('Cannot connect to proxy.', ConnectionResetError(104, 'Connection reset by peer')))

During handling of the above exception, another exception occurred:

Traceback (most recent call last):
  File "/root/Xuggest_scrapy/AMA_ANALYSIS/analysis_request_header.py", line 300, in into_Sellers_list
    sellers_list_responses = myrequest_get(url=sellers_list_url,headers=headers)
  File "/root/Xuggest_scrapy/AMA_ANALYSIS/analysis_request_header.py", line 256, in myrequest_get
    timeout=20
  File "/usr/lib/python3/dist-packages/requests/api.py", line 67, in get
    return request('get', url, params=params, **kwargs)
  File "/usr/lib/python3/dist-packages/requests/api.py", line 53, in request
    return session.request(method=method, url=url, **kwargs)
  File "/usr/lib/python3/dist-packages/requests/sessions.py", line 468, in request
    resp = self.send(prep, **send_kwargs)
  File "/usr/lib/python3/dist-packages/requests/sessions.py", line 576, in send
    r = adapter.send(request, **kwargs)
  File "/usr/lib/python3/dist-packages/requests/adapters.py", line 437, in send
    raise ConnectionError(e, request=request)
requests.exceptions.ConnectionError: HTTPSConnectionPool(host='www.amazon.com', port=443): Max retries exceeded with url: /gp/offer-listing/B0779MJ1P5/ref=dp_olp_new_mbc?ie=UTF8&condition=new (Caused by ProxyError('Cannot connect to proxy.', ConnectionResetError(104, 'Connection reset by peer')))
2018-10-05 04:40:31 [analysis_log] ERROR: into_Sellers_list
Traceback (most recent call last):
  File "/usr/lib/python3/dist-packages/urllib3/connectionpool.py", line 555, in urlopen
    self._prepare_proxy(conn)
  File "/usr/lib/python3/dist-packages/urllib3/connectionpool.py", line 753, in _prepare_proxy
    conn.connect()
  File "/usr/lib/python3/dist-packages/urllib3/connection.py", line 230, in connect
    self._tunnel()
  File "/usr/lib/python3.5/http/client.py", line 827, in _tunnel
    (version, code, message) = response._read_status()
  File "/usr/lib/python3.5/http/client.py", line 258, in _read_status
    line = str(self.fp.readline(_MAXLINE + 1), "iso-8859-1")
  File "/usr/lib/python3.5/socket.py", line 575, in readinto
    return self._sock.recv_into(b)
ConnectionResetError: [Errno 104] Connection reset by peer

During handling of the above exception, another exception occurred:

Traceback (most recent call last):
  File "/usr/lib/python3/dist-packages/requests/adapters.py", line 376, in send
    timeout=timeout
  File "/usr/lib/python3/dist-packages/urllib3/connectionpool.py", line 610, in urlopen
    _stacktrace=sys.exc_info()[2])
  File "/usr/lib/python3/dist-packages/urllib3/util/retry.py", line 273, in increment
    raise MaxRetryError(_pool, url, error or ResponseError(cause))
requests.packages.urllib3.exceptions.MaxRetryError: HTTPSConnectionPool(host='www.amazon.com', port=443): Max retries exceeded with url: /gp/offer-listing/B0779MJ1P5/ref=dp_olp_new_mbc?ie=UTF8&condition=new (Caused by ProxyError('Cannot connect to proxy.', ConnectionResetError(104, 'Connection reset by peer')))

During handling of the above exception, another exception occurred:

Traceback (most recent call last):
  File "/root/Xuggest_scrapy/AMA_ANALYSIS/analysis_request_header.py", line 300, in into_Sellers_list
    sellers_list_responses = myrequest_get(url=sellers_list_url,headers=headers)
  File "/root/Xuggest_scrapy/AMA_ANALYSIS/analysis_request_header.py", line 256, in myrequest_get
    timeout=20
  File "/usr/lib/python3/dist-packages/requests/api.py", line 67, in get
    return request('get', url, params=params, **kwargs)
  File "/usr/lib/python3/dist-packages/requests/api.py", line 53, in request
    return session.request(method=method, url=url, **kwargs)
  File "/usr/lib/python3/dist-packages/requests/sessions.py", line 468, in request
    resp = self.send(prep, **send_kwargs)
  File "/usr/lib/python3/dist-packages/requests/sessions.py", line 576, in send
    r = adapter.send(request, **kwargs)
  File "/usr/lib/python3/dist-packages/requests/adapters.py", line 437, in send
    raise ConnectionError(e, request=request)
requests.exceptions.ConnectionError: HTTPSConnectionPool(host='www.amazon.com', port=443): Max retries exceeded with url: /gp/offer-listing/B0779MJ1P5/ref=dp_olp_new_mbc?ie=UTF8&condition=new (Caused by ProxyError('Cannot connect to proxy.', ConnectionResetError(104, 'Connection reset by peer')))
2018-10-05 04:40:31 [analysis_log] ERROR: sellers_list_responses
Traceback (most recent call last):
  File "/root/Xuggest_scrapy/AMA_ANALYSIS/USA_analysis.py", line 1067, in Available
    sellers_list_responses = into_Sellers_list(sellers_list_url)
  File "/root/Xuggest_scrapy/AMA_ANALYSIS/analysis_request_header.py", line 305, in into_Sellers_list
    return sellers_list_responses
UnboundLocalError: local variable 'sellers_list_responses' referenced before assignment
2018-10-05 04:40:31 [analysis_log] ERROR: USA_USA_second_Analysis
Traceback (most recent call last):
  File "/root/Xuggest_scrapy/AMA_ANALYSIS/use_analysis.py", line 79, in USA_analysis
    USA_second_Analysis(ASIN=ASIN,stock=Stock,sellers_list_url=sellers_list_url,product_info=product_info,offerListingID=offerListingID)
  File "/root/Xuggest_scrapy/AMA_ANALYSIS/USA_analysis.py", line 1198, in USA_second_Analysis
    usa_second_product_obj.Available(sellers_list_url=sellers_list_url,ASIN=ASIN)
  File "/root/Xuggest_scrapy/AMA_ANALYSIS/USA_analysis.py", line 1072, in Available
    etree_html = etree.HTML(sellers_list_responses)
UnboundLocalError: local variable 'sellers_list_responses' referenced before assignment
2018-10-05 04:40:34 [analysis_log] ERROR: into_Sellers_list
Traceback (most recent call last):
  File "/usr/lib/python3/dist-packages/urllib3/connectionpool.py", line 555, in urlopen
    self._prepare_proxy(conn)
  File "/usr/lib/python3/dist-packages/urllib3/connectionpool.py", line 753, in _prepare_proxy
    conn.connect()
  File "/usr/lib/python3/dist-packages/urllib3/connection.py", line 230, in connect
    self._tunnel()
  File "/usr/lib/python3.5/http/client.py", line 827, in _tunnel
    (version, code, message) = response._read_status()
  File "/usr/lib/python3.5/http/client.py", line 258, in _read_status
    line = str(self.fp.readline(_MAXLINE + 1), "iso-8859-1")
  File "/usr/lib/python3.5/socket.py", line 575, in readinto
    return self._sock.recv_into(b)
ConnectionResetError: [Errno 104] Connection reset by peer

During handling of the above exception, another exception occurred:

Traceback (most recent call last):
  File "/usr/lib/python3/dist-packages/requests/adapters.py", line 376, in send
    timeout=timeout
  File "/usr/lib/python3/dist-packages/urllib3/connectionpool.py", line 610, in urlopen
    _stacktrace=sys.exc_info()[2])
  File "/usr/lib/python3/dist-packages/urllib3/util/retry.py", line 273, in increment
    raise MaxRetryError(_pool, url, error or ResponseError(cause))
requests.packages.urllib3.exceptions.MaxRetryError: HTTPSConnectionPool(host='www.amazon.com', port=443): Max retries exceeded with url: /gp/offer-listing/B001DEGKMO/ref=dp_olp_new_mbc?ie=UTF8&condition=new (Caused by ProxyError('Cannot connect to proxy.', ConnectionResetError(104, 'Connection reset by peer')))

During handling of the above exception, another exception occurred:

Traceback (most recent call last):
  File "/root/Xuggest_scrapy/AMA_ANALYSIS/analysis_request_header.py", line 300, in into_Sellers_list
    sellers_list_responses = myrequest_get(url=sellers_list_url,headers=headers)
  File "/root/Xuggest_scrapy/AMA_ANALYSIS/analysis_request_header.py", line 256, in myrequest_get
    timeout=20
  File "/usr/lib/python3/dist-packages/requests/api.py", line 67, in get
    return request('get', url, params=params, **kwargs)
  File "/usr/lib/python3/dist-packages/requests/api.py", line 53, in request
    return session.request(method=method, url=url, **kwargs)
  File "/usr/lib/python3/dist-packages/requests/sessions.py", line 468, in request
    resp = self.send(prep, **send_kwargs)
  File "/usr/lib/python3/dist-packages/requests/sessions.py", line 576, in send
    r = adapter.send(request, **kwargs)
  File "/usr/lib/python3/dist-packages/requests/adapters.py", line 437, in send
    raise ConnectionError(e, request=request)
requests.exceptions.ConnectionError: HTTPSConnectionPool(host='www.amazon.com', port=443): Max retries exceeded with url: /gp/offer-listing/B001DEGKMO/ref=dp_olp_new_mbc?ie=UTF8&condition=new (Caused by ProxyError('Cannot connect to proxy.', ConnectionResetError(104, 'Connection reset by peer')))
2018-10-05 04:40:34 [analysis_log] ERROR: into_Sellers_list
Traceback (most recent call last):
  File "/usr/lib/python3/dist-packages/urllib3/connectionpool.py", line 555, in urlopen
    self._prepare_proxy(conn)
  File "/usr/lib/python3/dist-packages/urllib3/connectionpool.py", line 753, in _prepare_proxy
    conn.connect()
  File "/usr/lib/python3/dist-packages/urllib3/connection.py", line 230, in connect
    self._tunnel()
  File "/usr/lib/python3.5/http/client.py", line 827, in _tunnel
    (version, code, message) = response._read_status()
  File "/usr/lib/python3.5/http/client.py", line 258, in _read_status
    line = str(self.fp.readline(_MAXLINE + 1), "iso-8859-1")
  File "/usr/lib/python3.5/socket.py", line 575, in readinto
    return self._sock.recv_into(b)
ConnectionResetError: [Errno 104] Connection reset by peer

During handling of the above exception, another exception occurred:

Traceback (most recent call last):
  File "/usr/lib/python3/dist-packages/requests/adapters.py", line 376, in send
    timeout=timeout
  File "/usr/lib/python3/dist-packages/urllib3/connectionpool.py", line 610, in urlopen
    _stacktrace=sys.exc_info()[2])
  File "/usr/lib/python3/dist-packages/urllib3/util/retry.py", line 273, in increment
    raise MaxRetryError(_pool, url, error or ResponseError(cause))
requests.packages.urllib3.exceptions.MaxRetryError: HTTPSConnectionPool(host='www.amazon.com', port=443): Max retries exceeded with url: /gp/offer-listing/B001DEGKMO/ref=dp_olp_new_mbc?ie=UTF8&condition=new (Caused by ProxyError('Cannot connect to proxy.', ConnectionResetError(104, 'Connection reset by peer')))

During handling of the above exception, another exception occurred:

Traceback (most recent call last):
  File "/root/Xuggest_scrapy/AMA_ANALYSIS/analysis_request_header.py", line 300, in into_Sellers_list
    sellers_list_responses = myrequest_get(url=sellers_list_url,headers=headers)
  File "/root/Xuggest_scrapy/AMA_ANALYSIS/analysis_request_header.py", line 256, in myrequest_get
    timeout=20
  File "/usr/lib/python3/dist-packages/requests/api.py", line 67, in get
    return request('get', url, params=params, **kwargs)
  File "/usr/lib/python3/dist-packages/requests/api.py", line 53, in request
    return session.request(method=method, url=url, **kwargs)
  File "/usr/lib/python3/dist-packages/requests/sessions.py", line 468, in request
    resp = self.send(prep, **send_kwargs)
  File "/usr/lib/python3/dist-packages/requests/sessions.py", line 576, in send
    r = adapter.send(request, **kwargs)
  File "/usr/lib/python3/dist-packages/requests/adapters.py", line 437, in send
    raise ConnectionError(e, request=request)
requests.exceptions.ConnectionError: HTTPSConnectionPool(host='www.amazon.com', port=443): Max retries exceeded with url: /gp/offer-listing/B001DEGKMO/ref=dp_olp_new_mbc?ie=UTF8&condition=new (Caused by ProxyError('Cannot connect to proxy.', ConnectionResetError(104, 'Connection reset by peer')))
2018-10-05 04:40:34 [analysis_log] ERROR: sellers_list_responses
Traceback (most recent call last):
  File "/root/Xuggest_scrapy/AMA_ANALYSIS/USA_analysis.py", line 1067, in Available
    sellers_list_responses = into_Sellers_list(sellers_list_url)
  File "/root/Xuggest_scrapy/AMA_ANALYSIS/analysis_request_header.py", line 305, in into_Sellers_list
    return sellers_list_responses
UnboundLocalError: local variable 'sellers_list_responses' referenced before assignment
2018-10-05 04:40:34 [analysis_log] ERROR: USA_USA_second_Analysis
Traceback (most recent call last):
  File "/root/Xuggest_scrapy/AMA_ANALYSIS/use_analysis.py", line 79, in USA_analysis
    USA_second_Analysis(ASIN=ASIN,stock=Stock,sellers_list_url=sellers_list_url,product_info=product_info,offerListingID=offerListingID)
  File "/root/Xuggest_scrapy/AMA_ANALYSIS/USA_analysis.py", line 1198, in USA_second_Analysis
    usa_second_product_obj.Available(sellers_list_url=sellers_list_url,ASIN=ASIN)
  File "/root/Xuggest_scrapy/AMA_ANALYSIS/USA_analysis.py", line 1072, in Available
    etree_html = etree.HTML(sellers_list_responses)
UnboundLocalError: local variable 'sellers_list_responses' referenced before assignment
2018-10-05 04:41:00 [analysis_log] ERROR: into_Sellers_list
Traceback (most recent call last):
  File "/usr/lib/python3/dist-packages/urllib3/connectionpool.py", line 555, in urlopen
    self._prepare_proxy(conn)
  File "/usr/lib/python3/dist-packages/urllib3/connectionpool.py", line 753, in _prepare_proxy
    conn.connect()
  File "/usr/lib/python3/dist-packages/urllib3/connection.py", line 230, in connect
    self._tunnel()
  File "/usr/lib/python3.5/http/client.py", line 827, in _tunnel
    (version, code, message) = response._read_status()
  File "/usr/lib/python3.5/http/client.py", line 258, in _read_status
    line = str(self.fp.readline(_MAXLINE + 1), "iso-8859-1")
  File "/usr/lib/python3.5/socket.py", line 575, in readinto
    return self._sock.recv_into(b)
ConnectionResetError: [Errno 104] Connection reset by peer

During handling of the above exception, another exception occurred:

Traceback (most recent call last):
  File "/usr/lib/python3/dist-packages/requests/adapters.py", line 376, in send
    timeout=timeout
  File "/usr/lib/python3/dist-packages/urllib3/connectionpool.py", line 610, in urlopen
    _stacktrace=sys.exc_info()[2])
  File "/usr/lib/python3/dist-packages/urllib3/util/retry.py", line 273, in increment
    raise MaxRetryError(_pool, url, error or ResponseError(cause))
requests.packages.urllib3.exceptions.MaxRetryError: HTTPSConnectionPool(host='www.amazon.com', port=443): Max retries exceeded with url: /gp/offer-listing/B078JX2YDZ/ref=dp_olp_new_mbc?ie=UTF8&condition=new (Caused by ProxyError('Cannot connect to proxy.', ConnectionResetError(104, 'Connection reset by peer')))

During handling of the above exception, another exception occurred:

Traceback (most recent call last):
  File "/root/Xuggest_scrapy/AMA_ANALYSIS/analysis_request_header.py", line 300, in into_Sellers_list
    sellers_list_responses = myrequest_get(url=sellers_list_url,headers=headers)
  File "/root/Xuggest_scrapy/AMA_ANALYSIS/analysis_request_header.py", line 256, in myrequest_get
    timeout=20
  File "/usr/lib/python3/dist-packages/requests/api.py", line 67, in get
    return request('get', url, params=params, **kwargs)
  File "/usr/lib/python3/dist-packages/requests/api.py", line 53, in request
    return session.request(method=method, url=url, **kwargs)
  File "/usr/lib/python3/dist-packages/requests/sessions.py", line 468, in request
    resp = self.send(prep, **send_kwargs)
  File "/usr/lib/python3/dist-packages/requests/sessions.py", line 576, in send
    r = adapter.send(request, **kwargs)
  File "/usr/lib/python3/dist-packages/requests/adapters.py", line 437, in send
    raise ConnectionError(e, request=request)
requests.exceptions.ConnectionError: HTTPSConnectionPool(host='www.amazon.com', port=443): Max retries exceeded with url: /gp/offer-listing/B078JX2YDZ/ref=dp_olp_new_mbc?ie=UTF8&condition=new (Caused by ProxyError('Cannot connect to proxy.', ConnectionResetError(104, 'Connection reset by peer')))
2018-10-05 04:41:01 [analysis_log] ERROR: into_Sellers_list
Traceback (most recent call last):
  File "/usr/lib/python3/dist-packages/urllib3/connectionpool.py", line 555, in urlopen
    self._prepare_proxy(conn)
  File "/usr/lib/python3/dist-packages/urllib3/connectionpool.py", line 753, in _prepare_proxy
    conn.connect()
  File "/usr/lib/python3/dist-packages/urllib3/connection.py", line 230, in connect
    self._tunnel()
  File "/usr/lib/python3.5/http/client.py", line 827, in _tunnel
    (version, code, message) = response._read_status()
  File "/usr/lib/python3.5/http/client.py", line 258, in _read_status
    line = str(self.fp.readline(_MAXLINE + 1), "iso-8859-1")
  File "/usr/lib/python3.5/socket.py", line 575, in readinto
    return self._sock.recv_into(b)
ConnectionResetError: [Errno 104] Connection reset by peer

During handling of the above exception, another exception occurred:

Traceback (most recent call last):
  File "/usr/lib/python3/dist-packages/requests/adapters.py", line 376, in send
    timeout=timeout
  File "/usr/lib/python3/dist-packages/urllib3/connectionpool.py", line 610, in urlopen
    _stacktrace=sys.exc_info()[2])
  File "/usr/lib/python3/dist-packages/urllib3/util/retry.py", line 273, in increment
    raise MaxRetryError(_pool, url, error or ResponseError(cause))
requests.packages.urllib3.exceptions.MaxRetryError: HTTPSConnectionPool(host='www.amazon.com', port=443): Max retries exceeded with url: /gp/offer-listing/B078JX2YDZ/ref=dp_olp_new_mbc?ie=UTF8&condition=new (Caused by ProxyError('Cannot connect to proxy.', ConnectionResetError(104, 'Connection reset by peer')))

During handling of the above exception, another exception occurred:

Traceback (most recent call last):
  File "/root/Xuggest_scrapy/AMA_ANALYSIS/analysis_request_header.py", line 300, in into_Sellers_list
    sellers_list_responses = myrequest_get(url=sellers_list_url,headers=headers)
  File "/root/Xuggest_scrapy/AMA_ANALYSIS/analysis_request_header.py", line 256, in myrequest_get
    timeout=20
  File "/usr/lib/python3/dist-packages/requests/api.py", line 67, in get
    return request('get', url, params=params, **kwargs)
  File "/usr/lib/python3/dist-packages/requests/api.py", line 53, in request
    return session.request(method=method, url=url, **kwargs)
  File "/usr/lib/python3/dist-packages/requests/sessions.py", line 468, in request
    resp = self.send(prep, **send_kwargs)
  File "/usr/lib/python3/dist-packages/requests/sessions.py", line 576, in send
    r = adapter.send(request, **kwargs)
  File "/usr/lib/python3/dist-packages/requests/adapters.py", line 437, in send
    raise ConnectionError(e, request=request)
requests.exceptions.ConnectionError: HTTPSConnectionPool(host='www.amazon.com', port=443): Max retries exceeded with url: /gp/offer-listing/B078JX2YDZ/ref=dp_olp_new_mbc?ie=UTF8&condition=new (Caused by ProxyError('Cannot connect to proxy.', ConnectionResetError(104, 'Connection reset by peer')))
2018-10-05 04:41:01 [analysis_log] ERROR: sellers_list_responses
Traceback (most recent call last):
  File "/root/Xuggest_scrapy/AMA_ANALYSIS/USA_analysis.py", line 1067, in Available
    sellers_list_responses = into_Sellers_list(sellers_list_url)
  File "/root/Xuggest_scrapy/AMA_ANALYSIS/analysis_request_header.py", line 305, in into_Sellers_list
    return sellers_list_responses
UnboundLocalError: local variable 'sellers_list_responses' referenced before assignment
2018-10-05 04:41:02 [analysis_log] ERROR: USA_USA_second_Analysis
Traceback (most recent call last):
  File "/root/Xuggest_scrapy/AMA_ANALYSIS/use_analysis.py", line 79, in USA_analysis
    USA_second_Analysis(ASIN=ASIN,stock=Stock,sellers_list_url=sellers_list_url,product_info=product_info,offerListingID=offerListingID)
  File "/root/Xuggest_scrapy/AMA_ANALYSIS/USA_analysis.py", line 1198, in USA_second_Analysis
    usa_second_product_obj.Available(sellers_list_url=sellers_list_url,ASIN=ASIN)
  File "/root/Xuggest_scrapy/AMA_ANALYSIS/USA_analysis.py", line 1072, in Available
    etree_html = etree.HTML(sellers_list_responses)
UnboundLocalError: local variable 'sellers_list_responses' referenced before assignment
2018-10-05 04:41:05 [analysis_log] ERROR: into_Sellers_list
Traceback (most recent call last):
  File "/usr/lib/python3/dist-packages/urllib3/connectionpool.py", line 555, in urlopen
    self._prepare_proxy(conn)
  File "/usr/lib/python3/dist-packages/urllib3/connectionpool.py", line 753, in _prepare_proxy
    conn.connect()
  File "/usr/lib/python3/dist-packages/urllib3/connection.py", line 230, in connect
    self._tunnel()
  File "/usr/lib/python3.5/http/client.py", line 827, in _tunnel
    (version, code, message) = response._read_status()
  File "/usr/lib/python3.5/http/client.py", line 258, in _read_status
    line = str(self.fp.readline(_MAXLINE + 1), "iso-8859-1")
  File "/usr/lib/python3.5/socket.py", line 575, in readinto
    return self._sock.recv_into(b)
ConnectionResetError: [Errno 104] Connection reset by peer

During handling of the above exception, another exception occurred:

Traceback (most recent call last):
  File "/usr/lib/python3/dist-packages/requests/adapters.py", line 376, in send
    timeout=timeout
  File "/usr/lib/python3/dist-packages/urllib3/connectionpool.py", line 610, in urlopen
    _stacktrace=sys.exc_info()[2])
  File "/usr/lib/python3/dist-packages/urllib3/util/retry.py", line 273, in increment
    raise MaxRetryError(_pool, url, error or ResponseError(cause))
requests.packages.urllib3.exceptions.MaxRetryError: HTTPSConnectionPool(host='www.amazon.com', port=443): Max retries exceeded with url: /gp/offer-listing/B00EUCKDN8/ref=dp_olp_new_mbc?ie=UTF8&condition=new (Caused by ProxyError('Cannot connect to proxy.', ConnectionResetError(104, 'Connection reset by peer')))

During handling of the above exception, another exception occurred:

Traceback (most recent call last):
  File "/root/Xuggest_scrapy/AMA_ANALYSIS/analysis_request_header.py", line 300, in into_Sellers_list
    sellers_list_responses = myrequest_get(url=sellers_list_url,headers=headers)
  File "/root/Xuggest_scrapy/AMA_ANALYSIS/analysis_request_header.py", line 256, in myrequest_get
    timeout=20
  File "/usr/lib/python3/dist-packages/requests/api.py", line 67, in get
    return request('get', url, params=params, **kwargs)
  File "/usr/lib/python3/dist-packages/requests/api.py", line 53, in request
    return session.request(method=method, url=url, **kwargs)
  File "/usr/lib/python3/dist-packages/requests/sessions.py", line 468, in request
    resp = self.send(prep, **send_kwargs)
  File "/usr/lib/python3/dist-packages/requests/sessions.py", line 576, in send
    r = adapter.send(request, **kwargs)
  File "/usr/lib/python3/dist-packages/requests/adapters.py", line 437, in send
    raise ConnectionError(e, request=request)
requests.exceptions.ConnectionError: HTTPSConnectionPool(host='www.amazon.com', port=443): Max retries exceeded with url: /gp/offer-listing/B00EUCKDN8/ref=dp_olp_new_mbc?ie=UTF8&condition=new (Caused by ProxyError('Cannot connect to proxy.', ConnectionResetError(104, 'Connection reset by peer')))
2018-10-05 04:41:09 [analysis_log] ERROR: into_Sellers_list
Traceback (most recent call last):
  File "/usr/lib/python3/dist-packages/urllib3/connectionpool.py", line 555, in urlopen
    self._prepare_proxy(conn)
  File "/usr/lib/python3/dist-packages/urllib3/connectionpool.py", line 753, in _prepare_proxy
    conn.connect()
  File "/usr/lib/python3/dist-packages/urllib3/connection.py", line 230, in connect
    self._tunnel()
  File "/usr/lib/python3.5/http/client.py", line 827, in _tunnel
    (version, code, message) = response._read_status()
  File "/usr/lib/python3.5/http/client.py", line 258, in _read_status
    line = str(self.fp.readline(_MAXLINE + 1), "iso-8859-1")
  File "/usr/lib/python3.5/socket.py", line 575, in readinto
    return self._sock.recv_into(b)
ConnectionResetError: [Errno 104] Connection reset by peer

During handling of the above exception, another exception occurred:

Traceback (most recent call last):
  File "/usr/lib/python3/dist-packages/requests/adapters.py", line 376, in send
    timeout=timeout
  File "/usr/lib/python3/dist-packages/urllib3/connectionpool.py", line 610, in urlopen
    _stacktrace=sys.exc_info()[2])
  File "/usr/lib/python3/dist-packages/urllib3/util/retry.py", line 273, in increment
    raise MaxRetryError(_pool, url, error or ResponseError(cause))
requests.packages.urllib3.exceptions.MaxRetryError: HTTPSConnectionPool(host='www.amazon.com', port=443): Max retries exceeded with url: /gp/offer-listing/B00EUCKDN8/ref=dp_olp_new_mbc?ie=UTF8&condition=new (Caused by ProxyError('Cannot connect to proxy.', ConnectionResetError(104, 'Connection reset by peer')))

During handling of the above exception, another exception occurred:

Traceback (most recent call last):
  File "/root/Xuggest_scrapy/AMA_ANALYSIS/analysis_request_header.py", line 300, in into_Sellers_list
    sellers_list_responses = myrequest_get(url=sellers_list_url,headers=headers)
  File "/root/Xuggest_scrapy/AMA_ANALYSIS/analysis_request_header.py", line 256, in myrequest_get
    timeout=20
  File "/usr/lib/python3/dist-packages/requests/api.py", line 67, in get
    return request('get', url, params=params, **kwargs)
  File "/usr/lib/python3/dist-packages/requests/api.py", line 53, in request
    return session.request(method=method, url=url, **kwargs)
  File "/usr/lib/python3/dist-packages/requests/sessions.py", line 468, in request
    resp = self.send(prep, **send_kwargs)
  File "/usr/lib/python3/dist-packages/requests/sessions.py", line 576, in send
    r = adapter.send(request, **kwargs)
  File "/usr/lib/python3/dist-packages/requests/adapters.py", line 437, in send
    raise ConnectionError(e, request=request)
requests.exceptions.ConnectionError: HTTPSConnectionPool(host='www.amazon.com', port=443): Max retries exceeded with url: /gp/offer-listing/B00EUCKDN8/ref=dp_olp_new_mbc?ie=UTF8&condition=new (Caused by ProxyError('Cannot connect to proxy.', ConnectionResetError(104, 'Connection reset by peer')))
2018-10-05 04:41:09 [analysis_log] ERROR: sellers_list_responses
Traceback (most recent call last):
  File "/root/Xuggest_scrapy/AMA_ANALYSIS/USA_analysis.py", line 1067, in Available
    sellers_list_responses = into_Sellers_list(sellers_list_url)
  File "/root/Xuggest_scrapy/AMA_ANALYSIS/analysis_request_header.py", line 305, in into_Sellers_list
    return sellers_list_responses
UnboundLocalError: local variable 'sellers_list_responses' referenced before assignment
2018-10-05 04:41:09 [analysis_log] ERROR: USA_USA_second_Analysis
Traceback (most recent call last):
  File "/root/Xuggest_scrapy/AMA_ANALYSIS/use_analysis.py", line 79, in USA_analysis
    USA_second_Analysis(ASIN=ASIN,stock=Stock,sellers_list_url=sellers_list_url,product_info=product_info,offerListingID=offerListingID)
  File "/root/Xuggest_scrapy/AMA_ANALYSIS/USA_analysis.py", line 1198, in USA_second_Analysis
    usa_second_product_obj.Available(sellers_list_url=sellers_list_url,ASIN=ASIN)
  File "/root/Xuggest_scrapy/AMA_ANALYSIS/USA_analysis.py", line 1072, in Available
    etree_html = etree.HTML(sellers_list_responses)
UnboundLocalError: local variable 'sellers_list_responses' referenced before assignment
2018-10-05 04:41:36 [root] WARNING: 重复处理：https://www.amazon.com/YYCRAFT-Paddad-Snowflake-Applique-Christmas/dp/B06ZYLL2DT/ref=zg_bs_7756220011_72?_encoding=UTF8&psc=1&refRID=79K6NV4C30YSW6GQCN0H
2018-10-05 04:41:46 [root] WARNING: 重复处理：https://www.amazon.com/Expo-Shiny-Tulle-Spool-25-Yard/dp/B007RDZSA0/ref=zg_bs_12899121_73?_encoding=UTF8&psc=1&refRID=2279A41HB63SJEV295A2
